Workbook
Name tblSpilledLogs: #REF!

Sheet README
A1: Operating costs of Mooney LX-JCO
A2: 46047
A3: This guide outlines the workflow for tracking aircraft expenses, flight logs, and pilot contributions.
A4: Accurate data entry in the four data entry sheets is essential for the Dashboard to reflect the true financial balance for each member.
A6: 1. Primary Data Entry
A7: Sheet Expenses: Record all maintenance and fixed costs. Fill after you pay an invoice or collect a receivable.
A8: Click outside the table; use the handle at bottom right to add more rows to the table
A9: Input Date, Category (e.g., F-Annual visit), and FundSource.
A10: Input HTAmount (Net) and VATRate; the sheet calculates AmountOut (Total).
A11: Input negative value for a receivable
A12: Record ManHours for labor-related entries to track maintenance history.
A14: Sheet AVGAS: Records refueling activity. Fill after a refuel
A15: Click outside the table; use the handle at bottom right to add more rows to the table
A16: Refueling: Set Category to AVGAS, enter FundSource, TTCAmount, volAVGAS.
... A41: CommonPot Balance: Represents the remaining liquidity or deficit in the collective aircraft fund. It is mostly the contribution of the hangar

Sheet Dashboard
B1: Dashboard of expenses Mooney LX-JCO | P1: Shares of costs among pilots
P2: Flight costs shares
B3: Additional KPI data | E3: Flight durations recorded in sheet "Flights" | P3: {=_xlfn.LET( _xlpm.data, Pivots!D65:K70, _xlpm.rows, ROWS(_xlpm.data), _xlpm.cols, COLUMNS(_xlpm.data), INDEX(_xlpm.data, _xlfn.SEQUENCE(_xlpm.rows), _xlfn.SEQUENCE(1, _xlpm.cols)) )} -> Row Labels | Q3: 2020 | R3: 2021 | S3: 2022 | T3: 2023 | U3: 2024 | V3: 2025 | W3: 2026
B4: Column1 | C4: 2018 | D4: 2019 | E4: 2020 | F4: 2021 | G4: 2022 | H4: 2023 | I4: 2024 | J4: 2025 | K4: 2026 | P4: CommonPot | Q4: 0 | R4: 0 | S4: 435.19051 | T4: 0 | U4: 0 | V4: 0 | W4: 0
B5: Hobbs 1st January | C5: 979.9 | D5: =C6 -> 1065.1 | E5: =D6 -> 1076.6 | F5: =E6 -> 1109.2 | G5: =F6 -> 1178.6 | H5: =G6 -> 1294.6 | I5: =H6 -> 1379.6 | J5: =I6 -> 1459.3 | K5: =J6 -> 1530.8 | P5: Dominique | Q5: 0 | R5: 0 | S5: 0 | T5: 4154.8125 | U5: 0 | V5: 0 | W5: 0
B6: Hobbs end period | C6: 1065.1 | D6: 1076.6 | E6: 1109.2 | F6: 1178.6 | G6: 1294.6 | H6: 1379.6 | I6: 1459.3 | J6: 1530.8 | K6: 1530.81 | P6: Guy | Q6: 1041.3593 | R6: 0 | S6: 13614.906 | T6: 0 | U6: 0 | V6: 0 | W6: 0
B7: Year flight hours | C7: =C6-C5 -> 85.2 | D7: =D6-D5 -> 11.5 | E7: =GETPIVOTDATA("Sum of CTripHobbs",Pivots!$D$33,"Year",Pivots!E34) -> 2.8 | F7: =GETPIVOTDATA("Sum of CTripHobbs",Pivots!$D$33,"Year",Pivots!F34) -> 2.7 | G7: =GETPIVOTDATA("Sum of CTripHobbs",Pivots!$D$33,"Year",Pivots!G34) -> 3.9 | H7: =GETPIVOTDATA("Sum of CTripHobbs",Pivots!$D$33,"Year",Pivots!H34) -> 8.3 | I7: =GETPIVOTDATA("Sum of CTripHobbs",Pivots!$D$33,"Year",Pivots!I34) -> 3.8 | J7: =GETPIVOTDATA("Sum of CTripHobbs",Pivots!$D$33,"Year",Pivots!J34) -> 4.5 | K7: =GETPIVOTDATA("Sum of CTripHobbs",Pivots!$D$33,"Year",Pivots!K34) -> 0.01 | P7: Jacques | Q7: 0 | R7: 0 | S7: 0 | T7: 0 | U7: 4756.0482 | V7: 0 | W7: 0
P8: Vu Tien | Q8: 2198.4251 | R8: 7264.69 | S8: 3046.3336 | T8: 7854.6275 | U8: 5413.1184 | V8: 8818.278 | W8: 0.93016217
P10: Expenses shares among owners
Q11: {=_xlfn.LET(_xlpm.pivotYears, Pivots!$C$40:$K$40, _xlfn._xlws.FILTER(_xlpm.pivotYears, _xlpm.pivotYears >= 2020))} -> 2020 | R11: 2021 | S11: 2022 | T11: 2023 | U11: 2024 | V11: 2025 | W11: 2026
P12: {=_xlfn._xlws.SORT(_xlfn.UNIQUE(tblOwnership[PilotOwner]))} -> CommonPot | Q12: {=_xlfn.LET( _xlpm.pilots,_xlfn.ANCHORARRAY( P12), _xlpm.years,_xlfn.ANCHORARRAY( Q11), _xlfn.MAKEARRAY(ROWS(_xlpm.pilots), COLUMNS(_xlpm.years), _xlfn.LAMBDA(_xlpm.r,_xlpm.c, _xlfn.LET( _xlpm.p, INDEX(_xlpm.pilots, _xlpm.r), _xlpm.y, INDEX(_xlpm.years, _xlpm.c), _xlpm.share, _xlfn.XLOOKUP(1, (tblOwnership[PilotOwner]=_xlpm.p)*(tblOwnership[Year]=_xlpm.y), tblOwnership[Share], 0), _xlpm.totalExp, IFERROR(GETPIVOTDATA("Sum of AmountOut", Pivots!$B$39, "Year", _xlpm.y), 0), _xlpm.share * _xlpm.totalExp ) )) )} -> 0 | R12: 0 | S12: 0 | T12: 0 | U12: 0 | V12: 0 | W12: 0
C13: Grand Total | D13: {=_xlfn.LET(_xlpm.pivotYears, Pivots!$C$40:$K$40, _xlfn._xlws.FILTER(_xlpm.pivotYears, _xlpm.pivotYears >= 2018))} -> 2018 | E13: 2019 | F13: 2020 | G13: 2021 | H13: 2022 | I13: 2023 | J13: 2024 | K13: 2025 | L13: 2026 | P13: Dominique | Q13: 0 | R13: 0 | S13: 0 | T13: 0 | U13: 0 | V13: 0 | W13: 0
B14: Total expenses + Fuel | C14: =SUM(D14:L14) -> 45261.595 | D14: =GETPIVOTDATA("AmountOut",Pivots!$B$39,"Year",Pivots!C$40)+D19 -> 5781.5249 | E14: =(GETPIVOTDATA("AmountOut",Pivots!$B$39,"Year",Pivots!D$40)+GETPIVOTDATA("Sum of TTCAmount",Pivots!$C$26,"Year",Pivots!D$27)) -> -23356.87 | F14: =(GETPIVOTDATA("AmountOut",Pivots!$B$39,"Year",Pivots!E$40)+GETPIVOTDATA("Sum of TTCAmount",Pivots!$C$26,"Year",Pivots!E$27)) -> 3338.2168 | G14: =(GETPIVOTDATA("AmountOut",Pivots!$B$39,"Year",Pivots!F$40)+GETPIVOTDATA("Sum of TTCAmount",Pivots!$C$26,"Year",Pivots!F$27)) -> 7011.0604 | H14: =(GETPIVOTDATA("AmountOut",Pivots!$B$39,"Year",Pivots!G$40)+GETPIVOTDATA("Sum of TTCAmount",Pivots!$C$26,"Year",Pivots!G$27)) -> 18705.13 | I14: =(GETPIVOTDATA("AmountOut",Pivots!$B$39,"Year",Pivots!H$40)+GETPIVOTDATA("Sum of TTCAmount",Pivots!$C$26,"Year",Pivots!H$27)) -> 10820.727 | J14: =(GETPIVOTDATA("AmountOut",Pivots!$B$39,"Year",Pivots!I$40)+GETPIVOTDATA("Sum of TTCAmount",Pivots!$C$26,"Year",Pivots!I$27)) -> 12154.651 | K14: =(GETPIVOTDATA("AmountOut",Pivots!$B$39,"Year",Pivots!J$40)+GETPIVOTDATA("Sum of TTCAmount",Pivots!$C$26,"Year",Pivots!J$27)) -> 10059.745 | L14: =(GETPIVOTDATA("AmountOut",Pivots!$B$39,"Year",Pivots!K$40)+GETPIVOTDATA("Sum of TTCAmount",Pivots!$C$26,"Year",Pivots!K$27)) -> 747.41 | P14: Guy | Q14: 0 | R14: 0 | S14: 0 | T14: 0 | U14: 0 | V14: 0 | W14: 0
B15: Fixed expenses | C15: =SUM(D15:L15) -> 2701.5003 | D15: =GETPIVOTDATA("AmountOut",Pivots!$B$39,"Year",Pivots!C$40,"CategoryGroup","F") -> 139.1949 | E15: =GETPIVOTDATA("AmountOut",Pivots!$B$39,"Year",Pivots!D$40,"CategoryGroup","F") -> 159.12 | F15: =GETPIVOTDATA("AmountOut",Pivots!$B$39,"Year",Pivots!E$40,"CategoryGroup","F") -> 540.8325 | G15: =GETPIVOTDATA("AmountOut",Pivots!$B$39,"Year",Pivots!F$40,"CategoryGroup","F") -> 172.9704 | H15: =GETPIVOTDATA("AmountOut",Pivots!$B$39,"Year",Pivots!G$40,"CategoryGroup","F") -> 651.37 | I15: =GETPIVOTDATA("AmountOut",Pivots!$B$39,"Year",Pivots!H$40,"CategoryGroup","F") -> -1737.2 | J15: =GETPIVOTDATA("AmountOut",Pivots!$B$39,"Year",Pivots!I$40,"CategoryGroup","F") -> 933.9525 | K15: =GETPIVOTDATA("AmountOut",Pivots!$B$39,"Year",Pivots!J$40,"CategoryGroup","F") -> 1093.86 | L15: =GETPIVOTDATA("AmountOut",Pivots!$B$39,"Year",Pivots!K$40,"CategoryGroup","F") -> 747.4 | P15: Jacques | Q15: 180.2775 | R15: 57.6568 | S15: 782.96667 | T15: -123.34268 | U15: 471.89686 | V15: 0 | W15: 0
B16: Variable expenses + Fuel | C16: =SUM(D16:L16) -> 64674.691 | D16: =GETPIVOTDATA("AmountOut",Pivots!$B$39,"Year",Pivots!C$40,"CategoryGroup","V")+D19 -> 5642.33 | E16: =GETPIVOTDATA("AmountOut",Pivots!$B$39,"Year",Pivots!D$40,"CategoryGroup","V")+GETPIVOTDATA("Sum of TTCAmount",Pivots!$C$26,"Year",Pivots!D$27) -> 706.52 | F16: =GETPIVOTDATA("AmountOut",Pivots!$B$39,"Year",Pivots!E$40,"CategoryGroup","V")+GETPIVOTDATA("Sum of TTCAmount",Pivots!$C$26,"Year",Pivots!E$27) -> 2797.3843 | G16: =GETPIVOTDATA("AmountOut",Pivots!$B$39,"Year",Pivots!F$40,"CategoryGroup","V")+GETPIVOTDATA("Sum of TTCAmount",Pivots!$C$26,"Year",Pivots!F$27) -> 6838.09 | H16: =GETPIVOTDATA("AmountOut",Pivots!$B$39,"Year",Pivots!G$40,"CategoryGroup","V")+GETPIVOTDATA("Sum of TTCAmount",Pivots!$C$26,"Year",Pivots!G$27) -> 17910.96 | I16: =GETPIVOTDATA("AmountOut",Pivots!$B$39,"Year",Pivots!H$40,"CategoryGroup","V")+GETPIVOTDATA("Sum of TTCAmount",Pivots!$C$26,"Year",Pivots!H$27) -> 11583.99 | J16: =GETPIVOTDATA("AmountOut",Pivots!$B$39,"Year",Pivots!I$40,"CategoryGroup","V")+GETPIVOTDATA("Sum of TTCAmount",Pivots!$C$26,"Year",Pivots!I$27) -> 10377.128 | K16: =GETPIVOTDATA("AmountOut",Pivots!$B$39,"Year",Pivots!J$40,"CategoryGroup","V")+GETPIVOTDATA("Sum of TTCAmount",Pivots!$C$26,"Year",Pivots!J$27) -> 8818.278 | L16: =GETPIVOTDATA("AmountOut",Pivots!$B$39,"Year",Pivots!K$40,"CategoryGroup","V")+GETPIVOTDATA("Sum of TTCAmount",Pivots!$C$26,"Year",Pivots!K$27) -> 0.01 | P16: Vu Tien | Q16: 360.555 | R16: 115.3136 | S16: 1565.9333 | T16: -493.37072 | U16: 1887.5874 | V16: 1241.4672 | W16: 747.4
B17: Exceptional expenses | C17: =SUM(D17:L17) -> -22114.596 | D17: =GETPIVOTDATA("AmountOut",Pivots!$B$39,"Year",Pivots!C$40,"CategoryGroup","X") -> 0 | E17: =GETPIVOTDATA("AmountOut",Pivots!$B$39,"Year",Pivots!D$40,"CategoryGroup","X") -> -24222.51 | F17: =GETPIVOTDATA("AmountOut",Pivots!$B$39,"Year",Pivots!E$40,"CategoryGroup","X") -> 0 | G17: =GETPIVOTDATA("AmountOut",Pivots!$B$39,"Year",Pivots!F$40,"CategoryGroup","X") -> 0 | H17: =GETPIVOTDATA("AmountOut",Pivots!$B$39,"Year",Pivots!G$40,"CategoryGroup","X") -> 142.8 | I17: =GETPIVOTDATA("AmountOut",Pivots!$B$39,"Year",Pivots!H$40,"CategoryGroup","X") -> 973.9366 | J17: =GETPIVOTDATA("AmountOut",Pivots!$B$39,"Year",Pivots!I$40,"CategoryGroup","X") -> 843.57 | K17: =GETPIVOTDATA("AmountOut",Pivots!$B$39,"Year",Pivots!J$40,"CategoryGroup","X") -> 147.6072 | L17: =GETPIVOTDATA("AmountOut",Pivots!$B$39,"Year",Pivots!K$40,"CategoryGroup","X") -> 0
B18: Variable expenses, except fuel | C18: =SUM(D18:L18) -> 2393.3418 | D18: =GETPIVOTDATA("AmountOut",Pivots!$B$39,"Year",Pivots!C$40,"CategoryGroup","V") -> 110.1 | E18: =GETPIVOTDATA("AmountOut",Pivots!$B$39,"Year",Pivots!D$40,"CategoryGroup","V") -> 0 | F18: =GETPIVOTDATA("AmountOut",Pivots!$B$39,"Year",Pivots!E$40,"CategoryGroup","V") -> 0 | G18: =GETPIVOTDATA("AmountOut",Pivots!$B$39,"Year",Pivots!F$40,"CategoryGroup","V") -> 0 | H18: =GETPIVOTDATA("AmountOut",Pivots!$B$39,"Year",Pivots!G$40,"CategoryGroup","V") -> 1554.73 | I18: =GETPIVOTDATA("AmountOut",Pivots!$B$39,"Year",Pivots!H$40,"CategoryGroup","V") -> 146.55 | J18: =GETPIVOTDATA("AmountOut",Pivots!$B$39,"Year",Pivots!I$40,"CategoryGroup","V") -> 581.9618 | K18: =GETPIVOTDATA("AmountOut",Pivots!$B$39,"Year",Pivots!J$40,"CategoryGroup","V") -> 0 | L18: =GETPIVOTDATA("AmountOut",Pivots!$B$39,"Year",Pivots!K$40,"CategoryGroup","V") -> 0 | P18: Contributions of pilots
B19: Fuel expenses (AVGAS) | C19: =SUM(D19:L19) -> 62281.349 | D19: =1077.38+4454.85 -> 5532.23 | E19: =GETPIVOTDATA("Sum of TTCAmount",Pivots!$C$26,"Year",Pivots!D$27) -> 706.52 | F19: =GETPIVOTDATA("Sum of TTCAmount",Pivots!$C$26,"Year",Pivots!E$27) -> 2797.3843 | G19: =GETPIVOTDATA("Sum of TTCAmount",Pivots!$C$26,"Year",Pivots!F$27) -> 6838.09 | H19: =GETPIVOTDATA("Sum of TTCAmount",Pivots!$C$26,"Year",Pivots!G$27) -> 16356.23 | I19: =GETPIVOTDATA("Sum of TTCAmount",Pivots!$C$26,"Year",Pivots!H$27) -> 11437.44 | J19: =GETPIVOTDATA("Sum of TTCAmount",Pivots!$C$26,"Year",Pivots!I$27) -> 9795.1666 | K19: =GETPIVOTDATA("Sum of TTCAmount",Pivots!$C$26,"Year",Pivots!J$27) -> 8818.278 | L19: =GETPIVOTDATA("Sum of TTCAmount",Pivots!$C$26,"Year",Pivots!K$27) -> 0.01 | P19: {=_xlfn.LET( _xlpm.data, Pivots!D49:K54, _xlpm.rows, ROWS(_xlpm.data), _xlpm.cols, COLUMNS(_xlpm.data), INDEX(_xlpm.data, _xlfn.SEQUENCE(_xlpm.rows), _xlfn.SEQUENCE(1, _xlpm.cols)) )} -> Row Labels | Q19: 2020 | R19: 2021 | S19: 2022 | T19: 2023 | U19: 2024 | V19: 2025 | W19: 2026
B20: Fuel volume (L) | C20: =SUM(D20:L20) -> 27439.184 | D20: =571.93+1830.35 -> 2402.28 | E20: =GETPIVOTDATA("Sum of volAVGAS_L",Pivots!$C$26,"Year",Pivots!D$27) -> 393.62 | F20: =GETPIVOTDATA("Sum of volAVGAS_L",Pivots!$C$26,"Year",Pivots!E$27) -> 1802.62 | G20: =GETPIVOTDATA("Sum of volAVGAS_L",Pivots!$C$26,"Year",Pivots!F$27) -> 3728.39 | H20: =GETPIVOTDATA("Sum of volAVGAS_L",Pivots!$C$26,"Year",Pivots!G$27) -> 6290.85 | I20: =GETPIVOTDATA("Sum of volAVGAS_L",Pivots!$C$26,"Year",Pivots!H$27) -> 4640.05 | J20: =GETPIVOTDATA("Sum of volAVGAS_L",Pivots!$C$26,"Year",Pivots!I$27) -> 4160.16 | K20: =GETPIVOTDATA("Sum of volAVGAS_L",Pivots!$C$26,"Year",Pivots!J$27) -> 4021.21 | L20: =GETPIVOTDATA("Sum of volAVGAS_L",Pivots!$C$26,"Year",Pivots!K$27) -> 0.0037037037 | P20: Dominique | Q20: 0 | R20: 2600 | S20: 4736.17 | T20: 3740.54 | U20: 0 | V20: 0 | W20: 0
B21: Fuel €/L | D21: =D19/D20 -> 2.3029081 | E21: =E19/E20 -> 1.7949291 | F21: =F19/F20 -> 1.5518436 | G21: =G19/G20 -> 1.8340597 | H21: =H19/H20 -> 2.6000032 | I21: =I19/I20 -> 2.464939 | J21: =J19/J20 -> 2.3545168 | K21: =K19/K20 -> 2.1929414 | L21: =L19/L20 -> 2.7 | P21: Guy | Q21: 3000 | R21: 6071.6 | S21: 6500 | T21: 3918.82 | U21: 2786.68 | V21: 2920 | W21: 0
B22: (Var. exp. + Fuel)/ (Total+Fuel) | D22: =D16/D14 -> 0.97592419 | E22: =((GETPIVOTDATA("AmountOut",Pivots!$B$39,"Year",Pivots!D$40,"CategoryGroup","V")+GETPIVOTDATA("Sum of TTCAmount",Pivots!$C$26,"Year",Pivots!D$27))/(GETPIVOTDATA("AmountOut",Pivots!$B$39,"Year",Pivots!D$40)+GETPIVOTDATA("Sum of TTCAmount",Pivots!$C$26,"Year",Pivots!D$27))) -> -0.030248916 | F22: =((GETPIVOTDATA("AmountOut",Pivots!$B$39,"Year",Pivots!E$40,"CategoryGroup","V")+GETPIVOTDATA("Sum of TTCAmount",Pivots!$C$26,"Year",Pivots!E$27))/(GETPIVOTDATA("AmountOut",Pivots!$B$39,"Year",Pivots!E$40)+GETPIVOTDATA("Sum of TTCAmount",Pivots!$C$26,"Year",Pivots!E$27))) -> 0.83798761 | G22: =((GETPIVOTDATA("AmountOut",Pivots!$B$39,"Year",Pivots!F$40,"CategoryGroup","V")+GETPIVOTDATA("Sum of TTCAmount",Pivots!$C$26,"Year",Pivots!F$27))/(GETPIVOTDATA("AmountOut",Pivots!$B$39,"Year",Pivots!F$40)+GETPIVOTDATA("Sum of TTCAmount",Pivots!$C$26,"Year",Pivots!F$27))) -> 0.97532892 | H22: =((GETPIVOTDATA("AmountOut",Pivots!$B$39,"Year",Pivots!G$40,"CategoryGroup","V")+GETPIVOTDATA("Sum of TTCAmount",Pivots!$C$26,"Year",Pivots!G$27))/(GETPIVOTDATA("AmountOut",Pivots!$B$39,"Year",Pivots!G$40)+GETPIVOTDATA("Sum of TTCAmount",Pivots!$C$26,"Year",Pivots!G$27))) -> 0.95754266 | I22: =((GETPIVOTDATA("AmountOut",Pivots!$B$39,"Year",Pivots!H$40,"CategoryGroup","V")+GETPIVOTDATA("Sum of TTCAmount",Pivots!$C$26,"Year",Pivots!H$27))/(GETPIVOTDATA("AmountOut",Pivots!$B$39,"Year",Pivots!H$40)+GETPIVOTDATA("Sum of TTCAmount",Pivots!$C$26,"Year",Pivots!H$27))) -> 1.0705372 | J22: =((GETPIVOTDATA("AmountOut",Pivots!$B$39,"Year",Pivots!I$40,"CategoryGroup","V")+GETPIVOTDATA("Sum of TTCAmount",Pivots!$C$26,"Year",Pivots!I$27))/(GETPIVOTDATA("AmountOut",Pivots!$B$39,"Year",Pivots!I$40)+GETPIVOTDATA("Sum of TTCAmount",Pivots!$C$26,"Year",Pivots!I$27))) -> 0.85375783 | K22: =((GETPIVOTDATA("AmountOut",Pivots!$B$39,"Year",Pivots!J$40,"CategoryGroup","V")+GETPIVOTDATA("Sum of TTCAmount",Pivots!$C$26,"Year",Pivots!J$27))/(GETPIVOTDATA("AmountOut",Pivots!$B$39,"Year",Pivots!J$40)+GETPIVOTDATA("Sum of TTCAmount",Pivots!$C$26,"Year",Pivots!J$27))) -> 0.87659059 | L22: =((GETPIVOTDATA("AmountOut",Pivots!$B$39,"Year",Pivots!K$40,"CategoryGroup","V")+GETPIVOTDATA("Sum of TTCAmount",Pivots!$C$26,"Year",Pivots!K$27))/(GETPIVOTDATA("AmountOut",Pivots!$B$39,"Year",Pivots!K$40)+GETPIVOTDATA("Sum of TTCAmount",Pivots!$C$26,"Year",Pivots!K$27))) -> 1.3379537e-05 | P22: Jacques | Q22: 5000 | R22: 3806.04 | S22: 20618.09 | T22: 12432.27 | U22: 23971.75 | V22: -1337 | W22: 0
B23: Fixed / (total+fuel) | D23: =D15/D14 -> 0.024075811 | E23: =GETPIVOTDATA("AmountOut",Pivots!$B$39,"Year",Pivots!D$40,"CategoryGroup","F")/(GETPIVOTDATA("AmountOut",Pivots!$B$39,"Year",Pivots!D$40)+GETPIVOTDATA("Sum of TTCAmount",Pivots!$C$26,"Year",Pivots!D$27)) -> -0.0068125566 | F23: =GETPIVOTDATA("AmountOut",Pivots!$B$39,"Year",Pivots!E$40,"CategoryGroup","F")/(GETPIVOTDATA("AmountOut",Pivots!$B$39,"Year",Pivots!E$40)+GETPIVOTDATA("Sum of TTCAmount",Pivots!$C$26,"Year",Pivots!E$27)) -> 0.16201239 | G23: =GETPIVOTDATA("AmountOut",Pivots!$B$39,"Year",Pivots!F$40,"CategoryGroup","F")/(GETPIVOTDATA("AmountOut",Pivots!$B$39,"Year",Pivots!F$40)+GETPIVOTDATA("Sum of TTCAmount",Pivots!$C$26,"Year",Pivots!F$27)) -> 0.024671075 | H23: =GETPIVOTDATA("AmountOut",Pivots!$B$39,"Year",Pivots!G$40,"CategoryGroup","F")/(GETPIVOTDATA("AmountOut",Pivots!$B$39,"Year",Pivots!G$40)+GETPIVOTDATA("Sum of TTCAmount",Pivots!$C$26,"Year",Pivots!G$27)) -> 0.034823067 | I23: =GETPIVOTDATA("AmountOut",Pivots!$B$39,"Year",Pivots!H$40,"CategoryGroup","F")/(GETPIVOTDATA("AmountOut",Pivots!$B$39,"Year",Pivots!H$40)+GETPIVOTDATA("Sum of TTCAmount",Pivots!$C$26,"Year",Pivots!H$27)) -> -0.16054375 | J23: =GETPIVOTDATA("AmountOut",Pivots!$B$39,"Year",Pivots!I$40,"CategoryGroup","F")/(GETPIVOTDATA("AmountOut",Pivots!$B$39,"Year",Pivots!I$40)+GETPIVOTDATA("Sum of TTCAmount",Pivots!$C$26,"Year",Pivots!I$27)) -> 0.076839105 | K23: =GETPIVOTDATA("AmountOut",Pivots!$B$39,"Year",Pivots!J$40,"CategoryGroup","F")/(GETPIVOTDATA("AmountOut",Pivots!$B$39,"Year",Pivots!J$40)+GETPIVOTDATA("Sum of TTCAmount",Pivots!$C$26,"Year",Pivots!J$27)) -> 0.10873635 | L23: =GETPIVOTDATA("AmountOut",Pivots!$B$39,"Year",Pivots!K$40,"CategoryGroup","F")/(GETPIVOTDATA("AmountOut",Pivots!$B$39,"Year",Pivots!K$40)+GETPIVOTDATA("Sum of TTCAmount",Pivots!$C$26,"Year",Pivots!K$27)) -> 0.99998662 | P23: Vu Tien | Q23: 28000 | R23: 21209.06 | S23: 39633.12 | T23: 38703.77 | U23: 46606.52 | V23: 43029.73 | W23: 3000
B24: Maintenance Labor m-h | D24: =GETPIVOTDATA("ManHour",Pivots!$B$58,"Year",Pivots!C$59) -> 3.25 | E24: =GETPIVOTDATA("ManHour",Pivots!$B$58,"Year",Pivots!D$59) -> 0 | F24: =GETPIVOTDATA("ManHour",Pivots!$B$58,"Year",Pivots!E$59) -> 0 | G24: =GETPIVOTDATA("ManHour",Pivots!$B$58,"Year",Pivots!F$59) -> 0 | H24: =GETPIVOTDATA("ManHour",Pivots!$B$58,"Year",Pivots!G$59) -> 0 | I24: =GETPIVOTDATA("ManHour",Pivots!$B$58,"Year",Pivots!H$59) -> 0 | J24: =GETPIVOTDATA("ManHour",Pivots!$B$58,"Year",Pivots!I$59) -> 2.5 | K24: =GETPIVOTDATA("ManHour",Pivots!$B$58,"Year",Pivots!J$59) -> 1.25 | L24: =GETPIVOTDATA("ManHour",Pivots!$B$58,"Year",Pivots!K$59) -> 0 | P24: CommonPot | Q24: 0 | R24: 0 | S24: 325.69 | T24: 4169.28 | U24: 3955.82 | V24: 364.62 | W24: 0
B26: (Variable expenses + Fuel ) / flight hour | D26: =D16/C7 -> 66.224531 | E26: =E16/D7 -> 61.436522 | F26: =F16/E7 -> 999.06584 | G26: =G16/F7 -> 2532.6259 | H26: =H16/G7 -> 4592.5538 | I26: =I16/H7 -> 1395.6614 | J26: =J16/I7 -> 2730.8233 | K26: =K16/J7 -> 1959.6173 | L26: =L16/K7 -> 1
B27: Fixed expenses/flight hour | D27: =D15/C7 -> 1.633743 | E27: =E15/D7 -> 13.836522 | F27: =F15/E7 -> 193.15446 | G27: =G15/F7 -> 64.063111 | H27: =H15/G7 -> 167.01795 | I27: =I15/H7 -> -209.3012 | J27: =J15/I7 -> 245.77697 | K27: =K15/J7 -> 243.08 | L27: =L15/K7 -> 74740
B28: Total expenses/flight hour | D28: =D26+D27 -> 67.858273 | E28: =E26+E27 -> 75.273043 | F28: =F26+F27 -> 1192.2203 | G28: =G26+G27 -> 2596.689 | H28: =H26+H27 -> 4759.5718 | I28: =I26+I27 -> 1186.3602 | J28: =J26+J27 -> 2976.6002 | K28: =K26+K27 -> 2202.6973 | L28: =L26+L27 -> 74741
B29: Maintenance/flight hour | D29: =D24/C7 -> 0.03814554 | E29: =E24/D7 -> 0 | F29: =F24/E7 -> 0 | G29: =G24/F7 -> 0 | H29: =H24/G7 -> 0 | I29: =I24/H7 -> 0 | J29: =J24/I7 -> 0.65789474 | K29: =K24/J7 -> 0.27777778 | L29: =L24/K7 -> 0
B30: Fuel costs/flight hour | D30: =D19/C7 -> 64.932277 | E30: =E19/D7 -> 61.436522 | F30: =F19/E7 -> 999.06584 | G30: =G19/F7 -> 2532.6259 | H30: =H19/G7 -> 4193.9051 | I30: =I19/H7 -> 1378.0048 | J30: =J19/I7 -> 2577.6754 | K30: =K19/J7 -> 1959.6173 | L30: =L19/K7 -> 1 | N30: =K28-K30 -> 243.08 | O30: In sheet Params,
B31: Fuel consumption(l) / flight hour | D31: =D20/C7 -> 28.195775 | E31: =E20/D7 -> 34.227826 | F31: =F20/E7 -> 643.79286 | G31: =G20/F7 -> 1380.8852 | H31: =H20/G7 -> 1613.0385 | I31: =I20/H7 -> 559.04217 | J31: =J20/I7 -> 1094.7789 | K31: =K20/J7 -> 893.60222 | L31: =L20/K7 -> 0.37037037 | O31: Dry price for externals=Total expenses/flight hour - Fuel costs / flight hour
B33: Hub hélice changé 2025 taraud abîmé, non amorti | D33: =GETPIVOTDATA("AmountOut",Pivots!$B$3,"Year",Pivots!J4,"Category","X-Change propeller hub") -> 0 | P33: Balance of pilots = Contributions - Flight costs - Expenses
B34: Landing gear, non amorti | D34: =GETPIVOTDATA("AmountOut",Pivots!$B$3,"Category","X-Landing gear replacement") -> -24222.51 | Q34: {=_xlfn.DROP(_xlfn.TAKE(_xlfn.ANCHORARRAY($P$3),1),,1)} -> 2020 | R34: 2021 | S34: 2022 | T34: 2023 | U34: 2024 | V34: 2025 | W34: 2026
B35: Tracteur, radeau, gilets, masques O2, non amortis | D35: =GETPIVOTDATA("AmountOut",Pivots!$B$3,"Category","X-Raft, Life vests, masks O2") -> 898.5366 | P35: {=_xlfn.LET( _xlpm.pilots, _xlfn.TOCOL( CHOOSE( {1,2,3}, _xlfn.DROP(_xlfn.TAKE(_xlfn.ANCHORARRAY($P$3),,1),1), _xlfn.DROP(_xlfn.TAKE(_xlfn.ANCHORARRAY($P$11),,1),1), _xlfn.DROP(_xlfn.TAKE(_xlfn.ANCHORARRAY($P$19),,1),1) ) ), _xlfn._xlws.SORT( _xlfn.UNIQUE( _xlfn._xlws.FILTER( _xlpm.pilots, ISTEXT(_xlpm.pilots) ) ) ) )} -> CommonPot | Q35: {=IFERROR( _xlfn.XLOOKUP( $P35, _xlfn.DROP(_xlfn.TAKE(_xlfn.ANCHORARRAY($P$19),,1),1), _xlfn.XLOOKUP( Q$34, _xlfn.DROP(_xlfn.TAKE(_xlfn.ANCHORARRAY($P$19),1),,1), _xlfn.DROP(_xlfn.ANCHORARRAY($P$19),1,1) ) ), 0 ) - IFERROR( _xlfn.XLOOKUP( $P35, _xlfn.DROP(_xlfn.TAKE(_xlfn.ANCHORARRAY($P$3),,1),1), _xlfn.XLOOKUP( Q$34, _xlfn.DROP(_xlfn.TAKE(_xlfn.ANCHORARRAY($P$3),1),,1), _xlfn.DROP(_xlfn.ANCHORARRAY($P$3),1,1) ) ), 0 ) - IFERROR( _xlfn.XLOOKUP( $P35, _xlfn.DROP(_xlfn.TAKE(_xlfn.ANCHORARRAY($P$11),,1),1), _xlfn.XLOOKUP( Q$34, _xlfn.DROP(_xlfn.TAKE(_xlfn.ANCHORARRAY($P$11),1),,1), _xlfn.DROP(_xlfn.ANCHORARRAY($P$11),1,1) ) ), 0 )} -> 0 | R35: {=IFERROR( _xlfn.XLOOKUP( $P35, _xlfn.DROP(_xlfn.TAKE(_xlfn.ANCHORARRAY($P$19),,1),1), _xlfn.XLOOKUP( R$34, _xlfn.DROP(_xlfn.TAKE(_xlfn.ANCHORARRAY($P$19),1),,1), _xlfn.DROP(_xlfn.ANCHORARRAY($P$19),1,1) ) ), 0 ) - IFERROR( _xlfn.XLOOKUP( $P35, _xlfn.DROP(_xlfn.TAKE(_xlfn.ANCHORARRAY($P$3),,1),1), _xlfn.XLOOKUP( R$34, _xlfn.DROP(_xlfn.TAKE(_xlfn.ANCHORARRAY($P$3),1),,1), _xlfn.DROP(_xlfn.ANCHORARRAY($P$3),1,1) ) ), 0 ) - IFERROR( _xlfn.XLOOKUP( $P35, _xlfn.DROP(_xlfn.TAKE(_xlfn.ANCHORARRAY($P$11),,1),1), _xlfn.XLOOKUP( R$34, _xlfn.DROP(_xlfn.TAKE(_xlfn.ANCHORARRAY($P$11),1),,1), _xlfn.DROP(_xlfn.ANCHORARRAY($P$11),1,1) ) ), 0 )} -> 0 | S35: {=IFERROR( _xlfn.XLOOKUP( $P35, _xlfn.DROP(_xlfn.TAKE(_xlfn.ANCHORARRAY($P$19),,1),1), _xlfn.XLOOKUP( S$34, _xlfn.DROP(_xlfn.TAKE(_xlfn.ANCHORARRAY($P$19),1),,1), _xlfn.DROP(_xlfn.ANCHORARRAY($P$19),1,1) ) ), 0 ) - IFERROR( _xlfn.XLOOKUP( $P35, _xlfn.DROP(_xlfn.TAKE(_xlfn.ANCHORARRAY($P$3),,1),1), _xlfn.XLOOKUP( S$34, _xlfn.DROP(_xlfn.TAKE(_xlfn.ANCHORARRAY($P$3),1),,1), _xlfn.DROP(_xlfn.ANCHORARRAY($P$3),1,1) ) ), 0 ) - IFERROR( _xlfn.XLOOKUP( $P35, _xlfn.DROP(_xlfn.TAKE(_xlfn.ANCHORARRAY($P$11),,1),1), _xlfn.XLOOKUP( S$34, _xlfn.DROP(_xlfn.TAKE(_xlfn.ANCHORARRAY($P$11),1),,1), _xlfn.DROP(_xlfn.ANCHORARRAY($P$11),1,1) ) ), 0 )} -> -109.50051 | T35: {=IFERROR( _xlfn.XLOOKUP( $P35, _xlfn.DROP(_xlfn.TAKE(_xlfn.ANCHORARRAY($P$19),,1),1), _xlfn.XLOOKUP( T$34, _xlfn.DROP(_xlfn.TAKE(_xlfn.ANCHORARRAY($P$19),1),,1), _xlfn.DROP(_xlfn.ANCHORARRAY($P$19),1,1) ) ), 0 ) - IFERROR( _xlfn.XLOOKUP( $P35, _xlfn.DROP(_xlfn.TAKE(_xlfn.ANCHORARRAY($P$3),,1),1), _xlfn.XLOOKUP( T$34, _xlfn.DROP(_xlfn.TAKE(_xlfn.ANCHORARRAY($P$3),1),,1), _xlfn.DROP(_xlfn.ANCHORARRAY($P$3),1,1) ) ), 0 ) - IFERROR( _xlfn.XLOOKUP( $P35, _xlfn.DROP(_xlfn.TAKE(_xlfn.ANCHORARRAY($P$11),,1),1), _xlfn.XLOOKUP( T$34, _xlfn.DROP(_xlfn.TAKE(_xlfn.ANCHORARRAY($P$11),1),,1), _xlfn.DROP(_xlfn.ANCHORARRAY($P$11),1,1) ) ), 0 )} -> 4169.28 | U35: {=IFERROR( _xlfn.XLOOKUP( $P35, _xlfn.DROP(_xlfn.TAKE(_xlfn.ANCHORARRAY($P$19),,1),1), _xlfn.XLOOKUP( U$34, _xlfn.DROP(_xlfn.TAKE(_xlfn.ANCHORARRAY($P$19),1),,1), _xlfn.DROP(_xlfn.ANCHORARRAY($P$19),1,1) ) ), 0 ) - IFERROR( _xlfn.XLOOKUP( $P35, _xlfn.DROP(_xlfn.TAKE(_xlfn.ANCHORARRAY($P$3),,1),1), _xlfn.XLOOKUP( U$34, _xlfn.DROP(_xlfn.TAKE(_xlfn.ANCHORARRAY($P$3),1),,1), _xlfn.DROP(_xlfn.ANCHORARRAY($P$3),1,1) ) ), 0 ) - IFERROR( _xlfn.XLOOKUP( $P35, _xlfn.DROP(_xlfn.TAKE(_xlfn.ANCHORARRAY($P$11),,1),1), _xlfn.XLOOKUP( U$34, _xlfn.DROP(_xlfn.TAKE(_xlfn.ANCHORARRAY($P$11),1),,1), _xlfn.DROP(_xlfn.ANCHORARRAY($P$11),1,1) ) ), 0 )} -> 3955.82 | V35: {=IFERROR( _xlfn.XLOOKUP( $P35, _xlfn.DROP(_xlfn.TAKE(_xlfn.ANCHORARRAY($P$19),,1),1), _xlfn.XLOOKUP( V$34, _xlfn.DROP(_xlfn.TAKE(_xlfn.ANCHORARRAY($P$19),1),,1), _xlfn.DROP(_xlfn.ANCHORARRAY($P$19),1,1) ) ), 0 ) - IFERROR( _xlfn.XLOOKUP( $P35, _xlfn.DROP(_xlfn.TAKE(_xlfn.ANCHORARRAY($P$3),,1),1), _xlfn.XLOOKUP( V$34, _xlfn.DROP(_xlfn.TAKE(_xlfn.ANCHORARRAY($P$3),1),,1), _xlfn.DROP(_xlfn.ANCHORARRAY($P$3),1,1) ) ), 0 ) - IFERROR( _xlfn.XLOOKUP( $P35, _xlfn.DROP(_xlfn.TAKE(_xlfn.ANCHORARRAY($P$11),,1),1), _xlfn.XLOOKUP( V$34, _xlfn.DROP(_xlfn.TAKE(_xlfn.ANCHORARRAY($P$11),1),,1), _xlfn.DROP(_xlfn.ANCHORARRAY($P$11),1,1) ) ), 0 )} -> 364.62 | W35: {=IFERROR( _xlfn.XLOOKUP( $P35, _xlfn.DROP(_xlfn.TAKE(_xlfn.ANCHORARRAY($P$19),,1),1), _xlfn.XLOOKUP( W$34, _xlfn.DROP(_xlfn.TAKE(_xlfn.ANCHORARRAY($P$19),1),,1), _xlfn.DROP(_xlfn.ANCHORARRAY($P$19),1,1) ) ), 0 ) - IFERROR( _xlfn.XLOOKUP( $P35, _xlfn.DROP(_xlfn.TAKE(_xlfn.ANCHORARRAY($P$3),,1),1), _xlfn.XLOOKUP( W$34, _xlfn.DROP(_xlfn.TAKE(_xlfn.ANCHORARRAY($P$3),1),,1), _xlfn.DROP(_xlfn.ANCHORARRAY($P$3),1,1) ) ), 0 ) - IFERROR( _xlfn.XLOOKUP( $P35, _xlfn.DROP(_xlfn.TAKE(_xlfn.ANCHORARRAY($P$11),,1),1), _xlfn.XLOOKUP( W$34, _xlfn.DROP(_xlfn.TAKE(_xlfn.ANCHORARRAY($P$11),1),,1), _xlfn.DROP(_xlfn.ANCHORARRAY($P$11),1,1) ) ), 0 )} -> 0
P36: Dominique | Q36: {=IFERROR( _xlfn.XLOOKUP( $P36, _xlfn.DROP(_xlfn.TAKE(_xlfn.ANCHORARRAY($P$19),,1),1), _xlfn.XLOOKUP( Q$34, _xlfn.DROP(_xlfn.TAKE(_xlfn.ANCHORARRAY($P$19),1),,1), _xlfn.DROP(_xlfn.ANCHORARRAY($P$19),1,1) ) ), 0 ) - IFERROR( _xlfn.XLOOKUP( $P36, _xlfn.DROP(_xlfn.TAKE(_xlfn.ANCHORARRAY($P$3),,1),1), _xlfn.XLOOKUP( Q$34, _xlfn.DROP(_xlfn.TAKE(_xlfn.ANCHORARRAY($P$3),1),,1), _xlfn.DROP(_xlfn.ANCHORARRAY($P$3),1,1) ) ), 0 ) - IFERROR( _xlfn.XLOOKUP( $P36, _xlfn.DROP(_xlfn.TAKE(_xlfn.ANCHORARRAY($P$11),,1),1), _xlfn.XLOOKUP( Q$34, _xlfn.DROP(_xlfn.TAKE(_xlfn.ANCHORARRAY($P$11),1),,1), _xlfn.DROP(_xlfn.ANCHORARRAY($P$11),1,1) ) ), 0 )} -> 0 | R36: {=IFERROR( _xlfn.XLOOKUP( $P36, _xlfn.DROP(_xlfn.TAKE(_xlfn.ANCHORARRAY($P$19),,1),1), _xlfn.XLOOKUP( R$34, _xlfn.DROP(_xlfn.TAKE(_xlfn.ANCHORARRAY($P$19),1),,1), _xlfn.DROP(_xlfn.ANCHORARRAY($P$19),1,1) ) ), 0 ) - IFERROR( _xlfn.XLOOKUP( $P36, _xlfn.DROP(_xlfn.TAKE(_xlfn.ANCHORARRAY($P$3),,1),1), _xlfn.XLOOKUP( R$34, _xlfn.DROP(_xlfn.TAKE(_xlfn.ANCHORARRAY($P$3),1),,1), _xlfn.DROP(_xlfn.ANCHORARRAY($P$3),1,1) ) ), 0 ) - IFERROR( _xlfn.XLOOKUP( $P36, _xlfn.DROP(_xlfn.TAKE(_xlfn.ANCHORARRAY($P$11),,1),1), _xlfn.XLOOKUP( R$34, _xlfn.DROP(_xlfn.TAKE(_xlfn.ANCHORARRAY($P$11),1),,1), _xlfn.DROP(_xlfn.ANCHORARRAY($P$11),1,1) ) ), 0 )} -> 2600 | S36: {=IFERROR( _xlfn.XLOOKUP( $P36, _xlfn.DROP(_xlfn.TAKE(_xlfn.ANCHORARRAY($P$19),,1),1), _xlfn.XLOOKUP( S$34, _xlfn.DROP(_xlfn.TAKE(_xlfn.ANCHORARRAY($P$19),1),,1), _xlfn.DROP(_xlfn.ANCHORARRAY($P$19),1,1) ) ), 0 ) - IFERROR( _xlfn.XLOOKUP( $P36, _xlfn.DROP(_xlfn.TAKE(_xlfn.ANCHORARRAY($P$3),,1),1), _xlfn.XLOOKUP( S$34, _xlfn.DROP(_xlfn.TAKE(_xlfn.ANCHORARRAY($P$3),1),,1), _xlfn.DROP(_xlfn.ANCHORARRAY($P$3),1,1) ) ), 0 ) - IFERROR( _xlfn.XLOOKUP( $P36, _xlfn.DROP(_xlfn.TAKE(_xlfn.ANCHORARRAY($P$11),,1),1), _xlfn.XLOOKUP( S$34, _xlfn.DROP(_xlfn.TAKE(_xlfn.ANCHORARRAY($P$11),1),,1), _xlfn.DROP(_xlfn.ANCHORARRAY($P$11),1,1) ) ), 0 )} -> 4736.17 | T36: {=IFERROR( _xlfn.XLOOKUP( $P36, _xlfn.DROP(_xlfn.TAKE(_xlfn.ANCHORARRAY($P$19),,1),1), _xlfn.XLOOKUP( T$34, _xlfn.DROP(_xlfn.TAKE(_xlfn.ANCHORARRAY($P$19),1),,1), _xlfn.DROP(_xlfn.ANCHORARRAY($P$19),1,1) ) ), 0 ) - IFERROR( _xlfn.XLOOKUP( $P36, _xlfn.DROP(_xlfn.TAKE(_xlfn.ANCHORARRAY($P$3),,1),1), _xlfn.XLOOKUP( T$34, _xlfn.DROP(_xlfn.TAKE(_xlfn.ANCHORARRAY($P$3),1),,1), _xlfn.DROP(_xlfn.ANCHORARRAY($P$3),1,1) ) ), 0 ) - IFERROR( _xlfn.XLOOKUP( $P36, _xlfn.DROP(_xlfn.TAKE(_xlfn.ANCHORARRAY($P$11),,1),1), _xlfn.XLOOKUP( T$34, _xlfn.DROP(_xlfn.TAKE(_xlfn.ANCHORARRAY($P$11),1),,1), _xlfn.DROP(_xlfn.ANCHORARRAY($P$11),1,1) ) ), 0 )} -> -414.27253 | U36: {=IFERROR( _xlfn.XLOOKUP( $P36, _xlfn.DROP(_xlfn.TAKE(_xlfn.ANCHORARRAY($P$19),,1),1), _xlfn.XLOOKUP( U$34, _xlfn.DROP(_xlfn.TAKE(_xlfn.ANCHORARRAY($P$19),1),,1), _xlfn.DROP(_xlfn.ANCHORARRAY($P$19),1,1) ) ), 0 ) - IFERROR( _xlfn.XLOOKUP( $P36, _xlfn.DROP(_xlfn.TAKE(_xlfn.ANCHORARRAY($P$3),,1),1), _xlfn.XLOOKUP( U$34, _xlfn.DROP(_xlfn.TAKE(_xlfn.ANCHORARRAY($P$3),1),,1), _xlfn.DROP(_xlfn.ANCHORARRAY($P$3),1,1) ) ), 0 ) - IFERROR( _xlfn.XLOOKUP( $P36, _xlfn.DROP(_xlfn.TAKE(_xlfn.ANCHORARRAY($P$11),,1),1), _xlfn.XLOOKUP( U$34, _xlfn.DROP(_xlfn.TAKE(_xlfn.ANCHORARRAY($P$11),1),,1), _xlfn.DROP(_xlfn.ANCHORARRAY($P$11),1,1) ) ), 0 )} -> 0 | V36: {=IFERROR( _xlfn.XLOOKUP( $P36, _xlfn.DROP(_xlfn.TAKE(_xlfn.ANCHORARRAY($P$19),,1),1), _xlfn.XLOOKUP( V$34, _xlfn.DROP(_xlfn.TAKE(_xlfn.ANCHORARRAY($P$19),1),,1), _xlfn.DROP(_xlfn.ANCHORARRAY($P$19),1,1) ) ), 0 ) - IFERROR( _xlfn.XLOOKUP( $P36, _xlfn.DROP(_xlfn.TAKE(_xlfn.ANCHORARRAY($P$3),,1),1), _xlfn.XLOOKUP( V$34, _xlfn.DROP(_xlfn.TAKE(_xlfn.ANCHORARRAY($P$3),1),,1), _xlfn.DROP(_xlfn.ANCHORARRAY($P$3),1,1) ) ), 0 ) - IFERROR( _xlfn.XLOOKUP( $P36, _xlfn.DROP(_xlfn.TAKE(_xlfn.ANCHORARRAY($P$11),,1),1), _xlfn.XLOOKUP( V$34, _xlfn.DROP(_xlfn.TAKE(_xlfn.ANCHORARRAY($P$11),1),,1), _xlfn.DROP(_xlfn.ANCHORARRAY($P$11),1,1) ) ), 0 )} -> 0 | W36: {=IFERROR( _xlfn.XLOOKUP( $P36, _xlfn.DROP(_xlfn.TAKE(_xlfn.ANCHORARRAY($P$19),,1),1), _xlfn.XLOOKUP( W$34, _xlfn.DROP(_xlfn.TAKE(_xlfn.ANCHORARRAY($P$19),1),,1), _xlfn.DROP(_xlfn.ANCHORARRAY($P$19),1,1) ) ), 0 ) - IFERROR( _xlfn.XLOOKUP( $P36, _xlfn.DROP(_xlfn.TAKE(_xlfn.ANCHORARRAY($P$3),,1),1), _xlfn.XLOOKUP( W$34, _xlfn.DROP(_xlfn.TAKE(_xlfn.ANCHORARRAY($P$3),1),,1), _xlfn.DROP(_xlfn.ANCHORARRAY($P$3),1,1) ) ), 0 ) - IFERROR( _xlfn.XLOOKUP( $P36, _xlfn.DROP(_xlfn.TAKE(_xlfn.ANCHORARRAY($P$11),,1),1), _xlfn.XLOOKUP( W$34, _xlfn.DROP(_xlfn.TAKE(_xlfn.ANCHORARRAY($P$11),1),,1), _xlfn.DROP(_xlfn.ANCHORARRAY($P$11),1,1) ) ), 0 )} -> 0
B37: Average Yearly Total expenses + Fuel | D37: =AVERAGE(D14:L14) -> 5029.0661 | P37: Guy | Q37: {=IFERROR( _xlfn.XLOOKUP( $P37, _xlfn.DROP(_xlfn.TAKE(_xlfn.ANCHORARRAY($P$19),,1),1), _xlfn.XLOOKUP( Q$34, _xlfn.DROP(_xlfn.TAKE(_xlfn.ANCHORARRAY($P$19),1),,1), _xlfn.DROP(_xlfn.ANCHORARRAY($P$19),1,1) ) ), 0 ) - IFERROR( _xlfn.XLOOKUP( $P37, _xlfn.DROP(_xlfn.TAKE(_xlfn.ANCHORARRAY($P$3),,1),1), _xlfn.XLOOKUP( Q$34, _xlfn.DROP(_xlfn.TAKE(_xlfn.ANCHORARRAY($P$3),1),,1), _xlfn.DROP(_xlfn.ANCHORARRAY($P$3),1,1) ) ), 0 ) - IFERROR( _xlfn.XLOOKUP( $P37, _xlfn.DROP(_xlfn.TAKE(_xlfn.ANCHORARRAY($P$11),,1),1), _xlfn.XLOOKUP( Q$34, _xlfn.DROP(_xlfn.TAKE(_xlfn.ANCHORARRAY($P$11),1),,1), _xlfn.DROP(_xlfn.ANCHORARRAY($P$11),1,1) ) ), 0 )} -> 1958.6407 | R37: {=IFERROR( _xlfn.XLOOKUP( $P37, _xlfn.DROP(_xlfn.TAKE(_xlfn.ANCHORARRAY($P$19),,1),1), _xlfn.XLOOKUP( R$34, _xlfn.DROP(_xlfn.TAKE(_xlfn.ANCHORARRAY($P$19),1),,1), _xlfn.DROP(_xlfn.ANCHORARRAY($P$19),1,1) ) ), 0 ) - IFERROR( _xlfn.XLOOKUP( $P37, _xlfn.DROP(_xlfn.TAKE(_xlfn.ANCHORARRAY($P$3),,1),1), _xlfn.XLOOKUP( R$34, _xlfn.DROP(_xlfn.TAKE(_xlfn.ANCHORARRAY($P$3),1),,1), _xlfn.DROP(_xlfn.ANCHORARRAY($P$3),1,1) ) ), 0 ) - IFERROR( _xlfn.XLOOKUP( $P37, _xlfn.DROP(_xlfn.TAKE(_xlfn.ANCHORARRAY($P$11),,1),1), _xlfn.XLOOKUP( R$34, _xlfn.DROP(_xlfn.TAKE(_xlfn.ANCHORARRAY($P$11),1),,1), _xlfn.DROP(_xlfn.ANCHORARRAY($P$11),1,1) ) ), 0 )} -> 6071.6 | S37: {=IFERROR( _xlfn.XLOOKUP( $P37, _xlfn.DROP(_xlfn.TAKE(_xlfn.ANCHORARRAY($P$19),,1),1), _xlfn.XLOOKUP( S$34, _xlfn.DROP(_xlfn.TAKE(_xlfn.ANCHORARRAY($P$19),1),,1), _xlfn.DROP(_xlfn.ANCHORARRAY($P$19),1,1) ) ), 0 ) - IFERROR( _xlfn.XLOOKUP( $P37, _xlfn.DROP(_xlfn.TAKE(_xlfn.ANCHORARRAY($P$3),,1),1), _xlfn.XLOOKUP( S$34, _xlfn.DROP(_xlfn.TAKE(_xlfn.ANCHORARRAY($P$3),1),,1), _xlfn.DROP(_xlfn.ANCHORARRAY($P$3),1,1) ) ), 0 ) - IFERROR( _xlfn.XLOOKUP( $P37, _xlfn.DROP(_xlfn.TAKE(_xlfn.ANCHORARRAY($P$11),,1),1), _xlfn.XLOOKUP( S$34, _xlfn.DROP(_xlfn.TAKE(_xlfn.ANCHORARRAY($P$11),1),,1), _xlfn.DROP(_xlfn.ANCHORARRAY($P$11),1,1) ) ), 0 )} -> -7114.9059 | T37: {=IFERROR( _xlfn.XLOOKUP( $P37, _xlfn.DROP(_xlfn.TAKE(_xlfn.ANCHORARRAY($P$19),,1),1), _xlfn.XLOOKUP( T$34, _xlfn.DROP(_xlfn.TAKE(_xlfn.ANCHORARRAY($P$19),1),,1), _xlfn.DROP(_xlfn.ANCHORARRAY($P$19),1,1) ) ), 0 ) - IFERROR( _xlfn.XLOOKUP( $P37, _xlfn.DROP(_xlfn.TAKE(_xlfn.ANCHORARRAY($P$3),,1),1), _xlfn.XLOOKUP( T$34, _xlfn.DROP(_xlfn.TAKE(_xlfn.ANCHORARRAY($P$3),1),,1), _xlfn.DROP(_xlfn.ANCHORARRAY($P$3),1,1) ) ), 0 ) - IFERROR( _xlfn.XLOOKUP( $P37, _xlfn.DROP(_xlfn.TAKE(_xlfn.ANCHORARRAY($P$11),,1),1), _xlfn.XLOOKUP( T$34, _xlfn.DROP(_xlfn.TAKE(_xlfn.ANCHORARRAY($P$11),1),,1), _xlfn.DROP(_xlfn.ANCHORARRAY($P$11),1,1) ) ), 0 )} -> 3918.82 | U37: {=IFERROR( _xlfn.XLOOKUP( $P37, _xlfn.DROP(_xlfn.TAKE(_xlfn.ANCHORARRAY($P$19),,1),1), _xlfn.XLOOKUP( U$34, _xlfn.DROP(_xlfn.TAKE(_xlfn.ANCHORARRAY($P$19),1),,1), _xlfn.DROP(_xlfn.ANCHORARRAY($P$19),1,1) ) ), 0 ) - IFERROR( _xlfn.XLOOKUP( $P37, _xlfn.DROP(_xlfn.TAKE(_xlfn.ANCHORARRAY($P$3),,1),1), _xlfn.XLOOKUP( U$34, _xlfn.DROP(_xlfn.TAKE(_xlfn.ANCHORARRAY($P$3),1),,1), _xlfn.DROP(_xlfn.ANCHORARRAY($P$3),1,1) ) ), 0 ) - IFERROR( _xlfn.XLOOKUP( $P37, _xlfn.DROP(_xlfn.TAKE(_xlfn.ANCHORARRAY($P$11),,1),1), _xlfn.XLOOKUP( U$34, _xlfn.DROP(_xlfn.TAKE(_xlfn.ANCHORARRAY($P$11),1),,1), _xlfn.DROP(_xlfn.ANCHORARRAY($P$11),1,1) ) ), 0 )} -> 2786.68 | V37: {=IFERROR( _xlfn.XLOOKUP( $P37, _xlfn.DROP(_xlfn.TAKE(_xlfn.ANCHORARRAY($P$19),,1),1), _xlfn.XLOOKUP( V$34, _xlfn.DROP(_xlfn.TAKE(_xlfn.ANCHORARRAY($P$19),1),,1), _xlfn.DROP(_xlfn.ANCHORARRAY($P$19),1,1) ) ), 0 ) - IFERROR( _xlfn.XLOOKUP( $P37, _xlfn.DROP(_xlfn.TAKE(_xlfn.ANCHORARRAY($P$3),,1),1), _xlfn.XLOOKUP( V$34, _xlfn.DROP(_xlfn.TAKE(_xlfn.ANCHORARRAY($P$3),1),,1), _xlfn.DROP(_xlfn.ANCHORARRAY($P$3),1,1) ) ), 0 ) - IFERROR( _xlfn.XLOOKUP( $P37, _xlfn.DROP(_xlfn.TAKE(_xlfn.ANCHORARRAY($P$11),,1),1), _xlfn.XLOOKUP( V$34, _xlfn.DROP(_xlfn.TAKE(_xlfn.ANCHORARRAY($P$11),1),,1), _xlfn.DROP(_xlfn.ANCHORARRAY($P$11),1,1) ) ), 0 )} -> 2920 | W37: {=IFERROR( _xlfn.XLOOKUP( $P37, _xlfn.DROP(_xlfn.TAKE(_xlfn.ANCHORARRAY($P$19),,1),1), _xlfn.XLOOKUP( W$34, _xlfn.DROP(_xlfn.TAKE(_xlfn.ANCHORARRAY($P$19),1),,1), _xlfn.DROP(_xlfn.ANCHORARRAY($P$19),1,1) ) ), 0 ) - IFERROR( _xlfn.XLOOKUP( $P37, _xlfn.DROP(_xlfn.TAKE(_xlfn.ANCHORARRAY($P$3),,1),1), _xlfn.XLOOKUP( W$34, _xlfn.DROP(_xlfn.TAKE(_xlfn.ANCHORARRAY($P$3),1),,1), _xlfn.DROP(_xlfn.ANCHORARRAY($P$3),1,1) ) ), 0 ) - IFERROR( _xlfn.XLOOKUP( $P37, _xlfn.DROP(_xlfn.TAKE(_xlfn.ANCHORARRAY($P$11),,1),1), _xlfn.XLOOKUP( W$34, _xlfn.DROP(_xlfn.TAKE(_xlfn.ANCHORARRAY($P$11),1),,1), _xlfn.DROP(_xlfn.ANCHORARRAY($P$11),1,1) ) ), 0 )} -> 0
B38: Average yearly fixed costs over the whole period | D38: =AVERAGE(Pivots!C41:'Pivots'!K41) -> 300.1667 | P38: Jacques | Q38: {=IFERROR( _xlfn.XLOOKUP( $P38, _xlfn.DROP(_xlfn.TAKE(_xlfn.ANCHORARRAY($P$19),,1),1), _xlfn.XLOOKUP( Q$34, _xlfn.DROP(_xlfn.TAKE(_xlfn.ANCHORARRAY($P$19),1),,1), _xlfn.DROP(_xlfn.ANCHORARRAY($P$19),1,1) ) ), 0 ) - IFERROR( _xlfn.XLOOKUP( $P38, _xlfn.DROP(_xlfn.TAKE(_xlfn.ANCHORARRAY($P$3),,1),1), _xlfn.XLOOKUP( Q$34, _xlfn.DROP(_xlfn.TAKE(_xlfn.ANCHORARRAY($P$3),1),,1), _xlfn.DROP(_xlfn.ANCHORARRAY($P$3),1,1) ) ), 0 ) - IFERROR( _xlfn.XLOOKUP( $P38, _xlfn.DROP(_xlfn.TAKE(_xlfn.ANCHORARRAY($P$11),,1),1), _xlfn.XLOOKUP( Q$34, _xlfn.DROP(_xlfn.TAKE(_xlfn.ANCHORARRAY($P$11),1),,1), _xlfn.DROP(_xlfn.ANCHORARRAY($P$11),1,1) ) ), 0 )} -> 5000 | R38: {=IFERROR( _xlfn.XLOOKUP( $P38, _xlfn.DROP(_xlfn.TAKE(_xlfn.ANCHORARRAY($P$19),,1),1), _xlfn.XLOOKUP( R$34, _xlfn.DROP(_xlfn.TAKE(_xlfn.ANCHORARRAY($P$19),1),,1), _xlfn.DROP(_xlfn.ANCHORARRAY($P$19),1,1) ) ), 0 ) - IFERROR( _xlfn.XLOOKUP( $P38, _xlfn.DROP(_xlfn.TAKE(_xlfn.ANCHORARRAY($P$3),,1),1), _xlfn.XLOOKUP( R$34, _xlfn.DROP(_xlfn.TAKE(_xlfn.ANCHORARRAY($P$3),1),,1), _xlfn.DROP(_xlfn.ANCHORARRAY($P$3),1,1) ) ), 0 ) - IFERROR( _xlfn.XLOOKUP( $P38, _xlfn.DROP(_xlfn.TAKE(_xlfn.ANCHORARRAY($P$11),,1),1), _xlfn.XLOOKUP( R$34, _xlfn.DROP(_xlfn.TAKE(_xlfn.ANCHORARRAY($P$11),1),,1), _xlfn.DROP(_xlfn.ANCHORARRAY($P$11),1,1) ) ), 0 )} -> 3806.04 | S38: {=IFERROR( _xlfn.XLOOKUP( $P38, _xlfn.DROP(_xlfn.TAKE(_xlfn.ANCHORARRAY($P$19),,1),1), _xlfn.XLOOKUP( S$34, _xlfn.DROP(_xlfn.TAKE(_xlfn.ANCHORARRAY($P$19),1),,1), _xlfn.DROP(_xlfn.ANCHORARRAY($P$19),1,1) ) ), 0 ) - IFERROR( _xlfn.XLOOKUP( $P38, _xlfn.DROP(_xlfn.TAKE(_xlfn.ANCHORARRAY($P$3),,1),1), _xlfn.XLOOKUP( S$34, _xlfn.DROP(_xlfn.TAKE(_xlfn.ANCHORARRAY($P$3),1),,1), _xlfn.DROP(_xlfn.ANCHORARRAY($P$3),1,1) ) ), 0 ) - IFERROR( _xlfn.XLOOKUP( $P38, _xlfn.DROP(_xlfn.TAKE(_xlfn.ANCHORARRAY($P$11),,1),1), _xlfn.XLOOKUP( S$34, _xlfn.DROP(_xlfn.TAKE(_xlfn.ANCHORARRAY($P$11),1),,1), _xlfn.DROP(_xlfn.ANCHORARRAY($P$11),1,1) ) ), 0 )} -> 20618.09 | T38: {=IFERROR( _xlfn.XLOOKUP( $P38, _xlfn.DROP(_xlfn.TAKE(_xlfn.ANCHORARRAY($P$19),,1),1), _xlfn.XLOOKUP( T$34, _xlfn.DROP(_xlfn.TAKE(_xlfn.ANCHORARRAY($P$19),1),,1), _xlfn.DROP(_xlfn.ANCHORARRAY($P$19),1,1) ) ), 0 ) - IFERROR( _xlfn.XLOOKUP( $P38, _xlfn.DROP(_xlfn.TAKE(_xlfn.ANCHORARRAY($P$3),,1),1), _xlfn.XLOOKUP( T$34, _xlfn.DROP(_xlfn.TAKE(_xlfn.ANCHORARRAY($P$3),1),,1), _xlfn.DROP(_xlfn.ANCHORARRAY($P$3),1,1) ) ), 0 ) - IFERROR( _xlfn.XLOOKUP( $P38, _xlfn.DROP(_xlfn.TAKE(_xlfn.ANCHORARRAY($P$11),,1),1), _xlfn.XLOOKUP( T$34, _xlfn.DROP(_xlfn.TAKE(_xlfn.ANCHORARRAY($P$11),1),,1), _xlfn.DROP(_xlfn.ANCHORARRAY($P$11),1,1) ) ), 0 )} -> 12432.27 | U38: {=IFERROR( _xlfn.XLOOKUP( $P38, _xlfn.DROP(_xlfn.TAKE(_xlfn.ANCHORARRAY($P$19),,1),1), _xlfn.XLOOKUP( U$34, _xlfn.DROP(_xlfn.TAKE(_xlfn.ANCHORARRAY($P$19),1),,1), _xlfn.DROP(_xlfn.ANCHORARRAY($P$19),1,1) ) ), 0 ) - IFERROR( _xlfn.XLOOKUP( $P38, _xlfn.DROP(_xlfn.TAKE(_xlfn.ANCHORARRAY($P$3),,1),1), _xlfn.XLOOKUP( U$34, _xlfn.DROP(_xlfn.TAKE(_xlfn.ANCHORARRAY($P$3),1),,1), _xlfn.DROP(_xlfn.ANCHORARRAY($P$3),1,1) ) ), 0 ) - IFERROR( _xlfn.XLOOKUP( $P38, _xlfn.DROP(_xlfn.TAKE(_xlfn.ANCHORARRAY($P$11),,1),1), _xlfn.XLOOKUP( U$34, _xlfn.DROP(_xlfn.TAKE(_xlfn.ANCHORARRAY($P$11),1),,1), _xlfn.DROP(_xlfn.ANCHORARRAY($P$11),1,1) ) ), 0 )} -> 19215.702 | V38: {=IFERROR( _xlfn.XLOOKUP( $P38, _xlfn.DROP(_xlfn.TAKE(_xlfn.ANCHORARRAY($P$19),,1),1), _xlfn.XLOOKUP( V$34, _xlfn.DROP(_xlfn.TAKE(_xlfn.ANCHORARRAY($P$19),1),,1), _xlfn.DROP(_xlfn.ANCHORARRAY($P$19),1,1) ) ), 0 ) - IFERROR( _xlfn.XLOOKUP( $P38, _xlfn.DROP(_xlfn.TAKE(_xlfn.ANCHORARRAY($P$3),,1),1), _xlfn.XLOOKUP( V$34, _xlfn.DROP(_xlfn.TAKE(_xlfn.ANCHORARRAY($P$3),1),,1), _xlfn.DROP(_xlfn.ANCHORARRAY($P$3),1,1) ) ), 0 ) - IFERROR( _xlfn.XLOOKUP( $P38, _xlfn.DROP(_xlfn.TAKE(_xlfn.ANCHORARRAY($P$11),,1),1), _xlfn.XLOOKUP( V$34, _xlfn.DROP(_xlfn.TAKE(_xlfn.ANCHORARRAY($P$11),1),,1), _xlfn.DROP(_xlfn.ANCHORARRAY($P$11),1,1) ) ), 0 )} -> -1337 | W38: {=IFERROR( _xlfn.XLOOKUP( $P38, _xlfn.DROP(_xlfn.TAKE(_xlfn.ANCHORARRAY($P$19),,1),1), _xlfn.XLOOKUP( W$34, _xlfn.DROP(_xlfn.TAKE(_xlfn.ANCHORARRAY($P$19),1),,1), _xlfn.DROP(_xlfn.ANCHORARRAY($P$19),1,1) ) ), 0 ) - IFERROR( _xlfn.XLOOKUP( $P38, _xlfn.DROP(_xlfn.TAKE(_xlfn.ANCHORARRAY($P$3),,1),1), _xlfn.XLOOKUP( W$34, _xlfn.DROP(_xlfn.TAKE(_xlfn.ANCHORARRAY($P$3),1),,1), _xlfn.DROP(_xlfn.ANCHORARRAY($P$3),1,1) ) ), 0 ) - IFERROR( _xlfn.XLOOKUP( $P38, _xlfn.DROP(_xlfn.TAKE(_xlfn.ANCHORARRAY($P$11),,1),1), _xlfn.XLOOKUP( W$34, _xlfn.DROP(_xlfn.TAKE(_xlfn.ANCHORARRAY($P$11),1),,1), _xlfn.DROP(_xlfn.ANCHORARRAY($P$11),1,1) ) ), 0 )} -> 0
B39: Average monthly fixed costs over 2018-2026 | D39: =D38/12 -> 25.013892 | P39: Vu Tien | Q39: {=IFERROR( _xlfn.XLOOKUP( $P39, _xlfn.DROP(_xlfn.TAKE(_xlfn.ANCHORARRAY($P$19),,1),1), _xlfn.XLOOKUP( Q$34, _xlfn.DROP(_xlfn.TAKE(_xlfn.ANCHORARRAY($P$19),1),,1), _xlfn.DROP(_xlfn.ANCHORARRAY($P$19),1,1) ) ), 0 ) - IFERROR( _xlfn.XLOOKUP( $P39, _xlfn.DROP(_xlfn.TAKE(_xlfn.ANCHORARRAY($P$3),,1),1), _xlfn.XLOOKUP( Q$34, _xlfn.DROP(_xlfn.TAKE(_xlfn.ANCHORARRAY($P$3),1),,1), _xlfn.DROP(_xlfn.ANCHORARRAY($P$3),1,1) ) ), 0 ) - IFERROR( _xlfn.XLOOKUP( $P39, _xlfn.DROP(_xlfn.TAKE(_xlfn.ANCHORARRAY($P$11),,1),1), _xlfn.XLOOKUP( Q$34, _xlfn.DROP(_xlfn.TAKE(_xlfn.ANCHORARRAY($P$11),1),,1), _xlfn.DROP(_xlfn.ANCHORARRAY($P$11),1,1) ) ), 0 )} -> 25801.575 | R39: {=IFERROR( _xlfn.XLOOKUP( $P39, _xlfn.DROP(_xlfn.TAKE(_xlfn.ANCHORARRAY($P$19),,1),1), _xlfn.XLOOKUP( R$34, _xlfn.DROP(_xlfn.TAKE(_xlfn.ANCHORARRAY($P$19),1),,1), _xlfn.DROP(_xlfn.ANCHORARRAY($P$19),1,1) ) ), 0 ) - IFERROR( _xlfn.XLOOKUP( $P39, _xlfn.DROP(_xlfn.TAKE(_xlfn.ANCHORARRAY($P$3),,1),1), _xlfn.XLOOKUP( R$34, _xlfn.DROP(_xlfn.TAKE(_xlfn.ANCHORARRAY($P$3),1),,1), _xlfn.DROP(_xlfn.ANCHORARRAY($P$3),1,1) ) ), 0 ) - IFERROR( _xlfn.XLOOKUP( $P39, _xlfn.DROP(_xlfn.TAKE(_xlfn.ANCHORARRAY($P$11),,1),1), _xlfn.XLOOKUP( R$34, _xlfn.DROP(_xlfn.TAKE(_xlfn.ANCHORARRAY($P$11),1),,1), _xlfn.DROP(_xlfn.ANCHORARRAY($P$11),1,1) ) ), 0 )} -> 13944.37 | S39: {=IFERROR( _xlfn.XLOOKUP( $P39, _xlfn.DROP(_xlfn.TAKE(_xlfn.ANCHORARRAY($P$19),,1),1), _xlfn.XLOOKUP( S$34, _xlfn.DROP(_xlfn.TAKE(_xlfn.ANCHORARRAY($P$19),1),,1), _xlfn.DROP(_xlfn.ANCHORARRAY($P$19),1,1) ) ), 0 ) - IFERROR( _xlfn.XLOOKUP( $P39, _xlfn.DROP(_xlfn.TAKE(_xlfn.ANCHORARRAY($P$3),,1),1), _xlfn.XLOOKUP( S$34, _xlfn.DROP(_xlfn.TAKE(_xlfn.ANCHORARRAY($P$3),1),,1), _xlfn.DROP(_xlfn.ANCHORARRAY($P$3),1,1) ) ), 0 ) - IFERROR( _xlfn.XLOOKUP( $P39, _xlfn.DROP(_xlfn.TAKE(_xlfn.ANCHORARRAY($P$11),,1),1), _xlfn.XLOOKUP( S$34, _xlfn.DROP(_xlfn.TAKE(_xlfn.ANCHORARRAY($P$11),1),,1), _xlfn.DROP(_xlfn.ANCHORARRAY($P$11),1,1) ) ), 0 )} -> 36586.786 | T39: {=IFERROR( _xlfn.XLOOKUP( $P39, _xlfn.DROP(_xlfn.TAKE(_xlfn.ANCHORARRAY($P$19),,1),1), _xlfn.XLOOKUP( T$34, _xlfn.DROP(_xlfn.TAKE(_xlfn.ANCHORARRAY($P$19),1),,1), _xlfn.DROP(_xlfn.ANCHORARRAY($P$19),1,1) ) ), 0 ) - IFERROR( _xlfn.XLOOKUP( $P39, _xlfn.DROP(_xlfn.TAKE(_xlfn.ANCHORARRAY($P$3),,1),1), _xlfn.XLOOKUP( T$34, _xlfn.DROP(_xlfn.TAKE(_xlfn.ANCHORARRAY($P$3),1),,1), _xlfn.DROP(_xlfn.ANCHORARRAY($P$3),1,1) ) ), 0 ) - IFERROR( _xlfn.XLOOKUP( $P39, _xlfn.DROP(_xlfn.TAKE(_xlfn.ANCHORARRAY($P$11),,1),1), _xlfn.XLOOKUP( T$34, _xlfn.DROP(_xlfn.TAKE(_xlfn.ANCHORARRAY($P$11),1),,1), _xlfn.DROP(_xlfn.ANCHORARRAY($P$11),1,1) ) ), 0 )} -> 30849.143 | U39: {=IFERROR( _xlfn.XLOOKUP( $P39, _xlfn.DROP(_xlfn.TAKE(_xlfn.ANCHORARRAY($P$19),,1),1), _xlfn.XLOOKUP( U$34, _xlfn.DROP(_xlfn.TAKE(_xlfn.ANCHORARRAY($P$19),1),,1), _xlfn.DROP(_xlfn.ANCHORARRAY($P$19),1,1) ) ), 0 ) - IFERROR( _xlfn.XLOOKUP( $P39, _xlfn.DROP(_xlfn.TAKE(_xlfn.ANCHORARRAY($P$3),,1),1), _xlfn.XLOOKUP( U$34, _xlfn.DROP(_xlfn.TAKE(_xlfn.ANCHORARRAY($P$3),1),,1), _xlfn.DROP(_xlfn.ANCHORARRAY($P$3),1,1) ) ), 0 ) - IFERROR( _xlfn.XLOOKUP( $P39, _xlfn.DROP(_xlfn.TAKE(_xlfn.ANCHORARRAY($P$11),,1),1), _xlfn.XLOOKUP( U$34, _xlfn.DROP(_xlfn.TAKE(_xlfn.ANCHORARRAY($P$11),1),,1), _xlfn.DROP(_xlfn.ANCHORARRAY($P$11),1,1) ) ), 0 )} -> 41193.402 | V39: {=IFERROR( _xlfn.XLOOKUP( $P39, _xlfn.DROP(_xlfn.TAKE(_xlfn.ANCHORARRAY($P$19),,1),1), _xlfn.XLOOKUP( V$34, _xlfn.DROP(_xlfn.TAKE(_xlfn.ANCHORARRAY($P$19),1),,1), _xlfn.DROP(_xlfn.ANCHORARRAY($P$19),1,1) ) ), 0 ) - IFERROR( _xlfn.XLOOKUP( $P39, _xlfn.DROP(_xlfn.TAKE(_xlfn.ANCHORARRAY($P$3),,1),1), _xlfn.XLOOKUP( V$34, _xlfn.DROP(_xlfn.TAKE(_xlfn.ANCHORARRAY($P$3),1),,1), _xlfn.DROP(_xlfn.ANCHORARRAY($P$3),1,1) ) ), 0 ) - IFERROR( _xlfn.XLOOKUP( $P39, _xlfn.DROP(_xlfn.TAKE(_xlfn.ANCHORARRAY($P$11),,1),1), _xlfn.XLOOKUP( V$34, _xlfn.DROP(_xlfn.TAKE(_xlfn.ANCHORARRAY($P$11),1),,1), _xlfn.DROP(_xlfn.ANCHORARRAY($P$11),1,1) ) ), 0 )} -> 34211.452 | W39: {=IFERROR( _xlfn.XLOOKUP( $P39, _xlfn.DROP(_xlfn.TAKE(_xlfn.ANCHORARRAY($P$19),,1),1), _xlfn.XLOOKUP( W$34, _xlfn.DROP(_xlfn.TAKE(_xlfn.ANCHORARRAY($P$19),1),,1), _xlfn.DROP(_xlfn.ANCHORARRAY($P$19),1,1) ) ), 0 ) - IFERROR( _xlfn.XLOOKUP( $P39, _xlfn.DROP(_xlfn.TAKE(_xlfn.ANCHORARRAY($P$3),,1),1), _xlfn.XLOOKUP( W$34, _xlfn.DROP(_xlfn.TAKE(_xlfn.ANCHORARRAY($P$3),1),,1), _xlfn.DROP(_xlfn.ANCHORARRAY($P$3),1,1) ) ), 0 ) - IFERROR( _xlfn.XLOOKUP( $P39, _xlfn.DROP(_xlfn.TAKE(_xlfn.ANCHORARRAY($P$11),,1),1), _xlfn.XLOOKUP( W$34, _xlfn.DROP(_xlfn.TAKE(_xlfn.ANCHORARRAY($P$11),1),,1), _xlfn.DROP(_xlfn.ANCHORARRAY($P$11),1,1) ) ), 0 )} -> 2999.0698

Sheet Expenses
A1: Date | B1: ExpenseName | C1: InvoiceName | D1: Category | E1: ManHour | F1: PilotPaying | G1: FundSource | H1: AmountIn | I1: HTAmount | J1: VATRate | K1: Year | L1: CategoryGroup | M1: VATAmount | N1: AmountOut
A2: 43109 | B2: Invoice insurance 20180109 of 9 January 2018 | C2: Assurance Allianz 2018 (taxe 4%) | D2: F-Plane insurance | E2: 0 | F2: Jacques | G2: Jacques | K2: =YEAR(tblExpenses[[#This Row],[Date]]) -> 2018 | L2: =LEFT(tblExpenses[[#This Row],[Category]],1) -> F | M2: =tblExpenses[[#This Row],[VATRate]]*tblExpenses[[#This Row],[HTAmount]] -> 0 | N2: =tblExpenses[[#This Row],[VATAmount]]+tblExpenses[[#This Row],[HTAmount]] -> 0
A3: 43218 | B3: Cigar Lighter placard replaced time 0,25 h | C3: GAM Invoice 2017337A of 23 Apr 2018 | D3: F-Labor (m-h) | E3: 0.25 | F3: Jacques | G3: Jacques | J3: 0.17 | K3: =YEAR(tblExpenses[[#This Row],[Date]]) -> 2018 | L3: =LEFT(tblExpenses[[#This Row],[Category]],1) -> F | M3: =tblExpenses[[#This Row],[VATRate]]*tblExpenses[[#This Row],[HTAmount]] -> 0 | N3: =tblExpenses[[#This Row],[VATAmount]]+tblExpenses[[#This Row],[HTAmount]] -> 0
A4: 43395 | B4: 2 x Tubes | C4: GAM Invoice 2018291 of 22 Oct 2018 | D4: F-Time limit-misc. structure | E4: 0 | F4: Jacques | G4: Jacques | I4: 118.97 | J4: 0.17 | K4: =YEAR(tblExpenses[[#This Row],[Date]]) -> 2018 | L4: =LEFT(tblExpenses[[#This Row],[Category]],1) -> F | M4: =tblExpenses[[#This Row],[VATRate]]*tblExpenses[[#This Row],[HTAmount]] -> 20.2249 | N4: =tblExpenses[[#This Row],[VATAmount]]+tblExpenses[[#This Row],[HTAmount]] -> 139.1949
A5: 43426 | B5: Maintenance Management labor 3 h | C5: GAM Invoice 2018231AMP of 8 Nov 2018 | D5: F-Labor (m-h) | E5: 3 | F5: Jacques | G5: Jacques | J5: 0.17 | K5: =YEAR(tblExpenses[[#This Row],[Date]]) -> 2018 | L5: =LEFT(tblExpenses[[#This Row],[Category]],1) -> F | M5: =tblExpenses[[#This Row],[VATRate]]*tblExpenses[[#This Row],[HTAmount]] -> 0 | N5: =tblExpenses[[#This Row],[VATAmount]]+tblExpenses[[#This Row],[HTAmount]] -> 0
A6: 43384 | B6: Handling Split 11/10/2018 | C6: Handling Split 11/10/2018 | D6: V-Landing fees | E6: 0 | F6: Vu Tien | G6: CommonPot | I6: 110.1 | J6: 0 | K6: =YEAR(tblExpenses[[#This Row],[Date]]) -> 2018 | L6: =LEFT(tblExpenses[[#This Row],[Category]],1) -> V | M6: =tblExpenses[[#This Row],[VATRate]]*tblExpenses[[#This Row],[HTAmount]] -> 0 | N6: =tblExpenses[[#This Row],[VATAmount]]+tblExpenses[[#This Row],[HTAmount]] -> 110.1
A7: 43515 | B7: Airspeed indicator test echanic costs 1,5 h | C7: GAM Invoice 2018343 of 19 February 2019 | D7: F-Time limit-misc. structure | E7: 0 | F7: Vu Tien | G7: CommonPot | I7: 136 | J7: 0.17 | K7: =YEAR(tblExpenses[[#This Row],[Date]]) -> 2019 | L7: =LEFT(tblExpenses[[#This Row],[Category]],1) -> F | M7: =tblExpenses[[#This Row],[VATRate]]*tblExpenses[[#This Row],[HTAmount]] -> 23.12 | N7: =tblExpenses[[#This Row],[VATAmount]]+tblExpenses[[#This Row],[HTAmount]] -> 159.12
A8: 43801 | B8: Hard landing: prepayment 2 | C8: GAM Invoice 2019061 of 2 December 2019 | D8: X-Landing gear replacement | E8: 0 | F8: Vu Tien | G8: CommonPot | I8: -20703 | J8: 0.17 | K8: =YEAR(tblExpenses[[#This Row],[Date]]) -> 2019 | L8: =LEFT(tblExpenses[[#This Row],[Category]],1) -> X | M8: =tblExpenses[[#This Row],[VATRate]]*tblExpenses[[#This Row],[HTAmount]] -> -3519.51 | N8: =tblExpenses[[#This Row],[VATAmount]]+tblExpenses[[#This Row],[HTAmount]] -> -24222.51
A9: 43832 | B9: Overhaul: 02 bottle freight | C9: GAM Invoice 2019343 of 2 December 2019 | D9: F-Refill. | E9: 0 | F9: Vu Tien | G9: CommonPot | I9: 180 | J9: 0.17 | K9: =YEAR(tblExpenses[[#This Row],[Date]]) -> 2020 | L9: =LEFT(tblExpenses[[#This Row],[Category]],1) -> F | M9: =tblExpenses[[#This Row],[VATRate]]*tblExpenses[[#This Row],[HTAmount]] -> 30.6 | N9: =tblExpenses[[#This Row],[VATAmount]]+tblExpenses[[#This Row],[HTAmount]] -> 210.6
A10: 43832 | B10: AD: Airworthiness directive on Bendix ignition switch costs 3 h + 0,25 h | C10: GAM Invoice 2019343 of 2 December 2019 | D10: F-Airworthiness dir. | E10: 0 | F10: Vu Tien | G10: CommonPot | I10: 282.25 | J10: 0.17 | K10: =YEAR(tblExpenses[[#This Row],[Date]]) -> 2020 | L10: =LEFT(tblExpenses[[#This Row],[Category]],1) -> F | M10: =tblExpenses[[#This Row],[VATRate]]*tblExpenses[[#This Row],[HTAmount]] -> 47.9825 | N10: =tblExpenses[[#This Row],[VATAmount]]+tblExpenses[[#This Row],[HTAmount]] -> 330.2325
A11: 43998 | B11: GAM Invoice 2020093A of 16 June 2020 | C11: GAM Invoice 2020093A of 16 June 2020 | D11: X-Change propeller hub | E11: 0 | F11: Vu Tien | G11: CommonPot | K11: =YEAR(tblExpenses[[#This Row],[Date]]) -> 2020 | L11: =LEFT(tblExpenses[[#This Row],[Category]],1) -> X | M11: =tblExpenses[[#This Row],[VATRate]]*tblExpenses[[#This Row],[HTAmount]] -> 0 | N11: =tblExpenses[[#This Row],[VATAmount]]+tblExpenses[[#This Row],[HTAmount]] -> 0
A12: 44203 | B12: Maintenance: Gasket | C12: GAM Invoice 2020296 of 7 January 2021 | D12: F-Annual visit | E12: 0 | F12: Vu Tien | G12: CommonPot | I12: 13.12 | J12: 0.17 | K12: =YEAR(tblExpenses[[#This Row],[Date]]) -> 2021 | L12: =LEFT(tblExpenses[[#This Row],[Category]],1) -> F | M12: =tblExpenses[[#This Row],[VATRate]]*tblExpenses[[#This Row],[HTAmount]] -> 2.2304 | N12: =tblExpenses[[#This Row],[VATAmount]]+tblExpenses[[#This Row],[HTAmount]] -> 15.3504
A13: 44260 | B13: Assurance: Ristourne | C13: Assurance: Ristourne | D13: F-Plane insurance | E13: 0 | F13: Vu Tien | G13: CommonPot | I13: -265 | J13: 0.17 | K13: =YEAR(tblExpenses[[#This Row],[Date]]) -> 2021 | L13: =LEFT(tblExpenses[[#This Row],[Category]],1) -> F | M13: =tblExpenses[[#This Row],[VATRate]]*tblExpenses[[#This Row],[HTAmount]] -> -45.05 | N13: =tblExpenses[[#This Row],[VATAmount]]+tblExpenses[[#This Row],[HTAmount]] -> -310.05
A14: 44425 | B14: Abonnement Jeppesen GTN650 | C14: Abonnement Jeppesen GTN650 | D14: F-Avionics | E14: 0 | F14: Vu Tien | G14: CommonPot | I14: 393 | J14: 0.19 | K14: =YEAR(tblExpenses[[#This Row],[Date]]) -> 2021 | L14: =LEFT(tblExpenses[[#This Row],[Category]],1) -> F | M14: =tblExpenses[[#This Row],[VATRate]]*tblExpenses[[#This Row],[HTAmount]] -> 74.67 | N14: =tblExpenses[[#This Row],[VATAmount]]+tblExpenses[[#This Row],[HTAmount]] -> 467.67
A15: 44539 | B15: Invoice 2021470AMP of 6 December 2021 | C15: Invoice 2021470AMP of 6 December 2021 | D15: F-ARC & CDN & ILR | E15: 0 | F15: Vu Tien | G15: CommonPot | K15: =YEAR(tblExpenses[[#This Row],[Date]]) -> 2021 | L15: =LEFT(tblExpenses[[#This Row],[Category]],1) -> F | M15: =tblExpenses[[#This Row],[VATRate]]*tblExpenses[[#This Row],[HTAmount]] -> 0 | N15: =tblExpenses[[#This Row],[VATAmount]]+tblExpenses[[#This Row],[HTAmount]] -> 0
A16: 44596 | B16: Invoice TNC DAC of 7 Feb 2022 | C16: Invoice TNC DAC of 7 Feb 2022 | D16: V-Landing fees | E16: 0 | F16: Vu Tien | G16: CommonPot | K16: =YEAR(tblExpenses[[#This Row],[Date]]) -> 2022 | L16: =LEFT(tblExpenses[[#This Row],[Category]],1) -> V | M16: =tblExpenses[[#This Row],[VATRate]]*tblExpenses[[#This Row],[HTAmount]] -> 0 | N16: =tblExpenses[[#This Row],[VATAmount]]+tblExpenses[[#This Row],[HTAmount]] -> 0
A17: 44649 | B17: Avionics: Troubleshooring avionics ILS GTN650-NAV2 | C17: Avionics: Troubleshooring avionics ILS GTN650-NAV2 | D17: X-GTN 650 | E17: 0 | F17: Vu Tien | G17: CommonPot | I17: 120 | J17: 0.19 | K17: =YEAR(tblExpenses[[#This Row],[Date]]) -> 2022 | L17: =LEFT(tblExpenses[[#This Row],[Category]],1) -> X | M17: =tblExpenses[[#This Row],[VATRate]]*tblExpenses[[#This Row],[HTAmount]] -> 22.8 | N17: =tblExpenses[[#This Row],[VATAmount]]+tblExpenses[[#This Row],[HTAmount]] -> 142.8
A18: 44746 | B18: Misc var: Taxes LuxAirport | C18: Invoice LuxAirport of 24 Jun 2022 | D18: V-Landing fees | E18: 0 | F18: Vu Tien | G18: CommonPot | I18: 70 | J18: 0 | K18: =YEAR(tblExpenses[[#This Row],[Date]]) -> 2022 | L18: =LEFT(tblExpenses[[#This Row],[Category]],1) -> V | M18: =tblExpenses[[#This Row],[VATRate]]*tblExpenses[[#This Row],[HTAmount]] -> 0 | N18: =tblExpenses[[#This Row],[VATAmount]]+tblExpenses[[#This Row],[HTAmount]] -> 70
A19: 44825 | B19: 100h: Working hours costs 13,5 | C19: GAM Invoice 2022173 of 21 Sept 2022 | D19: V-Visit 50h & 100h | E19: 0 | F19: Vu Tien | G19: CommonPot | I19: 1269 | J19: 0.17 | K19: =YEAR(tblExpenses[[#This Row],[Date]]) -> 2022 | L19: =LEFT(tblExpenses[[#This Row],[Category]],1) -> V | M19: =tblExpenses[[#This Row],[VATRate]]*tblExpenses[[#This Row],[HTAmount]] -> 215.73 | N19: =tblExpenses[[#This Row],[VATAmount]]+tblExpenses[[#This Row],[HTAmount]] -> 1484.73
A20: 44835 | B20: Hangar: Octobre | C20: Hangar: Octobre | D20: F-Hangar rent & insur. | E20: 0 | F20: Vu Tien | G20: CommonPot | I20: 651.37 | J20: 0 | K20: =YEAR(tblExpenses[[#This Row],[Date]]) -> 2022 | L20: =LEFT(tblExpenses[[#This Row],[Category]],1) -> F | M20: =tblExpenses[[#This Row],[VATRate]]*tblExpenses[[#This Row],[HTAmount]] -> 0 | N20: =tblExpenses[[#This Row],[VATAmount]]+tblExpenses[[#This Row],[HTAmount]] -> 651.37
A21: 44959 | B21: Misc. Fixed: Radeau sauvetage Lalizas, Friebe Flugbedarf | C21: Misc. Fixed: Radeau sauvetage Lalizas, Friebe Flugbedarf | D21: X-Raft, Life vests, masks O2 | E21: 0 | F21: Vu Tien | G21: CommonPot | I21: 767.98 | J21: 0.17 | K21: =YEAR(tblExpenses[[#This Row],[Date]]) -> 2023 | L21: =LEFT(tblExpenses[[#This Row],[Category]],1) -> X | M21: =tblExpenses[[#This Row],[VATRate]]*tblExpenses[[#This Row],[HTAmount]] -> 130.5566 | N21: =tblExpenses[[#This Row],[VATAmount]]+tblExpenses[[#This Row],[HTAmount]] -> 898.5366
A22: 44959 | B22: Variable material: Huile en bidon x8 | C22: Variable material: Huile en bidon x8 | D22: V-Oil & misc matériel | E22: 0 | F22: Vu Tien | G22: CommonPot | I22: 97.55 | J22: 0 | K22: =YEAR(tblExpenses[[#This Row],[Date]]) -> 2023 | L22: =LEFT(tblExpenses[[#This Row],[Category]],1) -> V | M22: =tblExpenses[[#This Row],[VATRate]]*tblExpenses[[#This Row],[HTAmount]] -> 0 | N22: =tblExpenses[[#This Row],[VATAmount]]+tblExpenses[[#This Row],[HTAmount]] -> 97.55
A23: 45076 | B23: Hébergement LX-ARA janvier à mai inclus | C23: Hébergement LX-ARA janvier à mai inclus | D23: F-Hangar rent & insur. | E23: 0 | F23: Vu Tien | G23: CommonPot | I23: -1737.2 | J23: 0 | K23: =YEAR(tblExpenses[[#This Row],[Date]]) -> 2023 | L23: =LEFT(tblExpenses[[#This Row],[Category]],1) -> F | M23: =tblExpenses[[#This Row],[VATRate]]*tblExpenses[[#This Row],[HTAmount]] -> 0 | N23: =tblExpenses[[#This Row],[VATAmount]]+tblExpenses[[#This Row],[HTAmount]] -> -1737.2
A24: 45090 | B24: Exceptional: Shipment Oxygen bottle empty | C24: GAM Invoice 2023081 of 3 Jun 2023 (CDN) | D24: X-Bottle O2 change | E24: 0 | F24: Vu Tien | G24: CommonPot | I24: 65 | J24: 0.16 | K24: =YEAR(tblExpenses[[#This Row],[Date]]) -> 2023 | L24: =LEFT(tblExpenses[[#This Row],[Category]],1) -> X | M24: =tblExpenses[[#This Row],[VATRate]]*tblExpenses[[#This Row],[HTAmount]] -> 10.4 | N24: =tblExpenses[[#This Row],[VATAmount]]+tblExpenses[[#This Row],[HTAmount]] -> 75.4
A25: 45086 | B25: Taxes LuxAirport mai 2023 | C25: Taxes LuxAirport mai 2023 | D25: V-Landing fees | E25: 0 | F25: Vu Tien | G25: CommonPot | I25: 49 | J25: 0 | K25: =YEAR(tblExpenses[[#This Row],[Date]]) -> 2023 | L25: =LEFT(tblExpenses[[#This Row],[Category]],1) -> V | M25: =tblExpenses[[#This Row],[VATRate]]*tblExpenses[[#This Row],[HTAmount]] -> 0 | N25: =tblExpenses[[#This Row],[VATAmount]]+tblExpenses[[#This Row],[HTAmount]] -> 49
A26: 45393 | B26: Brakes System hoses replace costs 7 h | C26: GAM Invoice 2023199 of 4 Avr 2024 | D26: X-OVH ducts | E26: 0 | F26: Vu Tien | G26: CommonPot | I26: 721 | J26: 0.17 | K26: =YEAR(tblExpenses[[#This Row],[Date]]) -> 2024 | L26: =LEFT(tblExpenses[[#This Row],[Category]],1) -> X | M26: =tblExpenses[[#This Row],[VATRate]]*tblExpenses[[#This Row],[HTAmount]] -> 122.57 | N26: =tblExpenses[[#This Row],[VATAmount]]+tblExpenses[[#This Row],[HTAmount]] -> 843.57
A27: 45393 | B27: AEROSHELL 15W50 DRUM, 15W50 DRUM | C27: GAM Invoice 2023199 of 4 Avr 2024 | D27: V-Oil & misc matériel | E27: 0 | F27: Vu Tien | G27: CommonPot | I27: 295.04 | J27: 0.17 | K27: =YEAR(tblExpenses[[#This Row],[Date]]) -> 2024 | L27: =LEFT(tblExpenses[[#This Row],[Category]],1) -> V | M27: =tblExpenses[[#This Row],[VATRate]]*tblExpenses[[#This Row],[HTAmount]] -> 50.1568 | N27: =tblExpenses[[#This Row],[VATAmount]]+tblExpenses[[#This Row],[HTAmount]] -> 345.1968
A28: 45393 | B28: Hourly rate Rudder Trim repair costs 6,5 h | C28: GAM Invoice 2023199 of 4 Avr 2024 | D28: F-Time limit-misc. structure | E28: 0 | F28: Vu Tien | G28: CommonPot | I28: 669.5 | J28: 0.17 | K28: =YEAR(tblExpenses[[#This Row],[Date]]) -> 2024 | L28: =LEFT(tblExpenses[[#This Row],[Category]],1) -> F | M28: =tblExpenses[[#This Row],[VATRate]]*tblExpenses[[#This Row],[HTAmount]] -> 113.815 | N28: =tblExpenses[[#This Row],[VATAmount]]+tblExpenses[[#This Row],[HTAmount]] -> 783.315
... A32: 45638 | B32: Hourly rate aircraft mechanic costs 1,25 | C32: Visit 50h 2024 | D32: V-Visit 50h & 100h | E32: 0 | F32: Vu Tien | G32: CommonPot | I32: 128.75 | J32: 0.17 | K32: =YEAR(tblExpenses[[#This Row],[Date]]) -> 2024 | L32: =LEFT(tblExpenses[[#This Row],[Category]],1) -> V | M32: =tblExpenses[[#This Row],[VATRate]]*tblExpenses[[#This Row],[HTAmount]] -> 21.8875 | N32: =tblExpenses[[#This Row],[VATAmount]]+tblExpenses[[#This Row],[HTAmount]] -> 150.6375
A33: 45638 | B33: Hourly rate aircraft mechanic time 1 h | C33: Visit 50h 2024 | D33: F-Labor (m-h) | E33: 1 | F33: Vu Tien | G33: CommonPot | J33: 0.17 | K33: =YEAR(tblExpenses[[#This Row],[Date]]) -> 2024 | L33: =LEFT(tblExpenses[[#This Row],[Category]],1) -> F | M33: =tblExpenses[[#This Row],[VATRate]]*tblExpenses[[#This Row],[HTAmount]] -> 0 | N33: =tblExpenses[[#This Row],[VATAmount]]+tblExpenses[[#This Row],[HTAmount]] -> 0
A34: 45662 | B34: Loyer hangar Luxairport jan-mar, moins contrib. LX-ARA | C34: Loyer hangar Luxairport jan-mar, moins contrib. LX-ARA | D34: F-Hangar rent & insur. | E34: 0 | F34: Vu Tien | G34: CommonPot | I34: 1093.86 | J34: 0 | K34: =YEAR(tblExpenses[[#This Row],[Date]]) -> 2025 | L34: =LEFT(tblExpenses[[#This Row],[Category]],1) -> F | M34: =tblExpenses[[#This Row],[VATRate]]*tblExpenses[[#This Row],[HTAmount]] -> 0 | N34: =tblExpenses[[#This Row],[VATAmount]]+tblExpenses[[#This Row],[HTAmount]] -> 1093.86
A35: 45804 | B35: GAM Invoice 2025060 of 27 May 2025 | C35: GAM Invoice 2025060 of 27 May 2025 | D35: V-Visit 50h & 100h | E35: 0 | F35: Vu Tien | G35: CommonPot | J35: 0 | K35: =YEAR(tblExpenses[[#This Row],[Date]]) -> 2025 | L35: =LEFT(tblExpenses[[#This Row],[Category]],1) -> V | M35: =tblExpenses[[#This Row],[VATRate]]*tblExpenses[[#This Row],[HTAmount]] -> 0 | N35: =tblExpenses[[#This Row],[VATAmount]]+tblExpenses[[#This Row],[HTAmount]] -> 0
A36: 45804 | B36: aircraft mechanic costs 2,5 h | C36: GAM Invoice 2025060 of 27 May 2025 | D36: X-OVH propeller governor | E36: 0 | F36: Vu Tien | G36: CommonPot | I36: 126.16 | J36: 0.17 | K36: =YEAR(tblExpenses[[#This Row],[Date]]) -> 2025 | L36: =LEFT(tblExpenses[[#This Row],[Category]],1) -> X | M36: =tblExpenses[[#This Row],[VATRate]]*tblExpenses[[#This Row],[HTAmount]] -> 21.4472 | N36: =tblExpenses[[#This Row],[VATAmount]]+tblExpenses[[#This Row],[HTAmount]] -> 147.6072
A37: 45804 | B37: aircraft mechanic time 0,25 h | C37: GAM Invoice 2025060 of 27 May 2025 | D37: F-Labor (m-h) | E37: 0.25 | F37: Vu Tien | G37: CommonPot | J37: 0.17 | K37: =YEAR(tblExpenses[[#This Row],[Date]]) -> 2025 | L37: =LEFT(tblExpenses[[#This Row],[Category]],1) -> F | M37: =tblExpenses[[#This Row],[VATRate]]*tblExpenses[[#This Row],[HTAmount]] -> 0 | N37: =tblExpenses[[#This Row],[VATAmount]]+tblExpenses[[#This Row],[HTAmount]] -> 0
A38: 45804 | B38: Customer : Both rear Nav-Lights inop | C38: GAM Invoice 2025060 of 27 May 2025 | D38: F-Avionics | E38: 0 | F38: Vu Tien | G38: CommonPot | J38: 0.17 | K38: =YEAR(tblExpenses[[#This Row],[Date]]) -> 2025 | L38: =LEFT(tblExpenses[[#This Row],[Category]],1) -> F | M38: =tblExpenses[[#This Row],[VATRate]]*tblExpenses[[#This Row],[HTAmount]] -> 0 | N38: =tblExpenses[[#This Row],[VATAmount]]+tblExpenses[[#This Row],[HTAmount]] -> 0
