Workbook
Name _VAT0: #REF!
Name _VAT1: #REF!
Name Man_hours: 'OLD-Data'!$J$2:$J$922
Name Montant: 'OLD-Data'!$H$2:$H$922
Name Prices: [1]Data!$D$2:$D$5
Name StatsType: 'OLD-Data'!$D$2:$D$922
Name StatsYear: 'OLD-Data'!$B$2:$B$922
Name VAT: #REF!
Name VAT_2023: #REF!
Name VAT0: #REF!
Name VFuelVol: 'OLD-Data'!$I$2:$I$443

Sheet OLD-Data
A1: Date | B1: Year | C1: Description | D1: Category | E1: AmountHT | F1: TVARate | G1: VATAmount | H1: AmountTTC | I1: AVGASLiters | J1: man-h
A2: 41312 | B2: =YEAR(A2) -> 2013 | C2: GAM Invoice 2013007 of 31 Jan 2013 | J2: 0
A3: 41312 | B3: =YEAR(A3) -> 2013 | C3: Engine Oil | D3: V-Oil & misc material | E3: 114.08 | F3: 0.15 | G3: =E3*F3 -> 17.112 | H3: =E3+G3 -> 131.192 | J3: 0
A4: 41312 | B4: =YEAR(A4) -> 2013 | C4: Maintenance: Oil analysis | D4: F-Annual visit | E4: 129.3 | F4: 0.15 | G4: =E4*F4 -> 19.395 | H4: =E4+G4 -> 148.695 | J4: 0
A5: 41312 | B5: =YEAR(A5) -> 2013 | C5: Maintenance: Filter, misc. | D5: F-Annual visit | E5: 161.41 | F5: 0.15 | G5: =E5*F5 -> 24.2115 | H5: =E5+G5 -> 185.6215 | J5: 0
A6: 41312 | B6: =YEAR(A6) -> 2013 | C6: Maintenance: Filter, misc. | D6: F-Manpwr & management (m-h) | F6: 0.15 | G6: =E6*F6 -> 0 | H6: =E6+G6 -> 0 | J6: 2
A7: 41312 | B7: =YEAR(A7) -> 2013 | C7: Maintenance: replace LH brake costs 5 h | D7: F-Time limit-misc. structure | E7: 335 | F7: 0.15 | G7: =E7*F7 -> 50.25 | H7: =E7+G7 -> 385.25 | J7: 0
A8: 41312 | B8: =YEAR(A8) -> 2013 | C8: Maintenance: replace LH brake time 5 h | D8: F-Manpwr & management (m-h) | F8: 0.15 | G8: =E8*F8 -> 0 | H8: =E8+G8 -> 0 | J8: 5
A9: 41312 | B9: =YEAR(A9) -> 2013 | C9: Maintenance Management 3 h | D9: F-Manpwr & management (m-h) | E9: 207 | F9: 0.15 | G9: =E9*F9 -> 31.05 | H9: =E9+G9 -> 238.05 | J9: 3
A10: 41312 | B10: =YEAR(A10) -> 2013 | C10: Annual: 100h & Annual Inspection Costs 19,5 h | D10: F-Annual visit | E10: 1307 | F10: 0.15 | G10: =E10*F10 -> 196.05 | H10: =E10+G10 -> 1503.05 | J10: 0
A11: 41312 | B11: =YEAR(A11) -> 2013 | C11: Annual: 100h & Annual Inspection time 19,5 h | D11: F-Manpwr & management (m-h) | F11: 0.15 | G11: =E11*F11 -> 0 | H11: =E11+G11 -> 0 | J11: 19.5
A12: 41312 | B12: =YEAR(A12) -> 2013 | C12: Avionics: Pitot Static Test costs 4 h | D12: F-Time limit-misc. structure | E12: 275 | F12: 0.15 | G12: =E12*F12 -> 41.25 | H12: =E12+G12 -> 316.25 | J12: 0
A13: 41312 | B13: =YEAR(A13) -> 2013 | C13: Avionics: Pitot Static Test time 4 h | D13: F-Manpwr & management (m-h) | F13: 0.15 | G13: =E13*F13 -> 0 | H13: =E13+G13 -> 0 | J13: 4
A14: 41312 | B14: =YEAR(A14) -> 2013 | C14: Avionics: Airspeed Indicator Test costs 1,5 h | D14: F-Time limit-misc. structure | E14: 93 | F14: 0.15 | G14: =E14*F14 -> 13.95 | H14: =E14+G14 -> 106.95 | J14: 0
A15: 41312 | B15: =YEAR(A15) -> 2013 | C15: Avionics: Airspeed Indicator Test time 1,5 h | D15: F-Manpwr & management (m-h) | F15: 0.15 | G15: =E15*F15 -> 0 | H15: =E15+G15 -> 0 | J15: 1.5
A16: 41312 | B16: =YEAR(A16) -> 2013 | C16: Avionics: Compass Calibration costs 3 h | D16: F-Time limit-misc. structure | E16: 200 | F16: 0.15 | G16: =E16*F16 -> 30 | H16: =E16+G16 -> 230 | J16: 0
A17: 41312 | B17: =YEAR(A17) -> 2013 | C17: Avionics: Compass Calibration time 3 h | D17: F-Manpwr & management (m-h) | F17: 0.15 | G17: =E17*F17 -> 0 | H17: =E17+G17 -> 0 | J17: 3
A18: 41386 | B18: =YEAR(A18) -> 2013 | C18: GAM Invoice 2013085 of 19 Apr 2013 | J18: 0
A19: 41386 | B19: =YEAR(A19) -> 2013 | C19: Maintenance: Hydraulic fluid | D19: F-Refill. | E19: 14.65 | F19: 0.15 | G19: =E19*F19 -> 2.1975 | H19: =E19+G19 -> 16.8475 | J19: 0
A20: 41386 | B20: =YEAR(A20) -> 2013 | C20: Maintenance: replace LH brake costs 3 h | D20: F-Time limit-misc. structure | E20: 201 | F20: 0.15 | G20: =E20*F20 -> 30.15 | H20: =E20+G20 -> 231.15 | J20: 0
A21: 41386 | B21: =YEAR(A21) -> 2013 | C21: Maintenance: replace LH brake time 3 h | D21: F-Manpwr & management (m-h) | F21: 0.15 | G21: =E21*F21 -> 0 | H21: =E21+G21 -> 0 | J21: 3
A22: 41476 | B22: =YEAR(A22) -> 2013 | C22: Invoice ALSA of 21 Jul 2015 | J22: 0
A23: 41476 | B23: =YEAR(A23) -> 2013 | C23: Redevance qualification avion 422 + RGD 2004 | D23: F-ARC & CDN & ILR | E23: 335 | F23: 0.17 | G23: =E23*F23 -> 56.95 | H23: =E23+G23 -> 391.95 | J23: 0
A24: 41476 | B24: =YEAR(A24) -> 2013 | C24: GAM Invoice 2013200E of 12 Jul 2013 | J24: 0
A25: 41476 | B25: =YEAR(A25) -> 2013 | C25: Engine extension | D25: F-ARC & CDN & ILR | E25: 200 | F25: 0.15 | G25: =E25*F25 -> 30 | H25: =E25+G25 -> 230 | J25: 0
A26: 41476 | B26: =YEAR(A26) -> 2013 | C26: GAM Invoice 2013200 of 12 Jul 2013 | J26: 0
A27: 41476 | B27: =YEAR(A27) -> 2013 | C27: Maintenance: Drain valve | D27: F-Time limit-misc. structure | E27: 37.76 | F27: 0.15 | G27: =E27*F27 -> 5.664 | H27: =E27+G27 -> 43.424 | J27: 0
A28: 41476 | B28: =YEAR(A28) -> 2013 | C28: Replace LH/RH fuel drain valve, stormscope repair costs 5,5 h | D28: F-Time limit-misc. structure | E28: 368.5 | F28: 0.15 | G28: =E28*F28 -> 55.275 | H28: =E28+G28 -> 423.775 | J28: 0
A29: 41476 | B29: =YEAR(A29) -> 2013 | C29: Replace work above time 5,5 h | D29: F-Manpwr & management (m-h) | F29: 0.15 | G29: =E29*F29 -> 0 | H29: =E29+G29 -> 0 | J29: 5.5
A30: 41481 | B30: =YEAR(A30) -> 2013 | C30: GAM Invoice 2013200C of 19 Jul 2013 | J30: 0
A31: 41481 | B31: =YEAR(A31) -> 2013 | C31: CDN Renewal | D31: F-ARC & CDN & ILR | E31: 730 | F31: 0.15 | G31: =E31*F31 -> 109.5 | H31: =E31+G31 -> 839.5 | J31: 0
A32: 41504 | B32: =YEAR(A32) -> 2013 | C32: Invoice ALSA of 31 Jul 2013 | J32: 0
A33: 41504 | B33: =YEAR(A33) -> 2013 | C33: Redevances ARC | D33: F-ARC & CDN & ILR | E33: 379.85 | F33: 0.15 | G33: =E33*F33 -> 56.9775 | H33: =E33+G33 -> 436.8275 | J33: 0
A34: 41504 | B34: =YEAR(A34) -> 2013 | C34: Invoice ALSA of 6 Aug 2013 | J34: 0
A35: 41504 | B35: =YEAR(A35) -> 2013 | C35: Extension potentiel moteur | D35: F-ARC & CDN & ILR | E35: 122.09 | F35: 0.15 | G35: =E35*F35 -> 18.3135 | H35: =E35+G35 -> 140.4035 | J35: 0
A36: 41709 | B36: =YEAR(A36) -> 2014 | C36: Invoice 2013366 of 9 Mar 2014 | J36: 0
A37: 41709 | B37: =YEAR(A37) -> 2014 | C37: Refill: O2 bottle & freight | D37: F-Refill. | E37: =581+150 -> 731 | F37: 0.15 | G37: =E37*F37 -> 109.65 | H37: =E37+G37 -> 840.65 | J37: 0
A38: 41709 | B38: =YEAR(A38) -> 2014 | C38: Var. Material: Engine oil | D38: V-Oil & misc material | E38: 123.98 | F38: 0.15 | G38: =E38*F38 -> 18.597 | H38: =E38+G38 -> 142.577 | J38: 0
A39: 41709 | B39: =YEAR(A39) -> 2014 | C39: Battery charger (x2) | D39: F-Time limit-misc. structure | E39: 480 | F39: 0.15 | G39: =E39*F39 -> 72 | H39: =E39+G39 -> 552 | J39: 0
A40: 41709 | B40: =YEAR(A40) -> 2014 | C40: Battery (x2) | D40: F-Time limit-misc. structure | E40: 1627.56 | F40: 0.15 | G40: =E40*F40 -> 244.134 | H40: =E40+G40 -> 1871.694 | J40: 0
...

Sheet OLD-Stats
A1: Mooney LX-JCO – Expense Statistics
A2: ne pas remplir directement
A3: Hourly operational rates from 2018-2024 | B3: =B10+B24 -> 8.1790411 | C3: Hourly rate of €390 fixed for external contractors in 2024 | M3: =M10+M24 -> -10.197843 | N3: =N10+N24 -> 10.539003 | O3: =O10+O24 -> 17.446796
A4: Hourly rate including exceptions since 2018 | B4: =B10+B24+B37 -> 96.152158
C5: 2013 | D5: 2014 | E5: 2015 | F5: 2016 | G5: 2017 | H5: 2018 | I5: 2019 | J5: 2020 | K5: 2021 | L5: 2022 | M5: 2023 | N5: 2024 | O5: 2025
A6: Hobbs at the beginning of the year | C6: 856.7 | D6: 905.6 | E6: 910.1 | F6: 951.1 | G6: 970.7 | H6: 979.9 | I6: 1065.1 | J6: 1076.6 | K6: 1109.2 | L6: 1178.6 | M6: 1294.6 | N6: 1379.6 | O6: 1459.3
A7: Hobbs end of year | C7: 905.6 | D7: 910.1 | E7: 951.1 | F7: 970.7 | G7: 979.9 | H7: 1065.1 | I7: 1076.6 | J7: 1109.2 | K7: 1178.6 | L7: 1294.6 | M7: 1379.6 | N7: 1459.3 | O7: 1530.8
A8: Flight hours for the year | C8: =C7-C6 -> 48.9 | D8: =D7-D6 -> 4.5 | E8: =E7-E6 -> 41 | F8: =F7-F6 -> 19.6 | G8: =G7-G6 -> 9.2 | H8: =H7-H6 -> 85.2 | I8: =I7-I6 -> 11.5 | J8: =J7-J6 -> 32.6 | ... O8: =O7-O6 -> 71.5 | Q8: =O7-C6 -> 674.1 | R8: HdV since 2013
A9: Recurring variable costs
A10: Variable hourly rate general since 2018 -> now | B10: =B11+B15 -> 1.6128233 | M10: =M11+M15 -> 1.7241176 | N10: =N11+N15 -> 2.5926913 | O10: =O11+O15 -> 0
A11: Variable hourly rate excluding fuel and taxes since 2018-> now | B11: =SUM(H12:N12)/SUM(H$8:N$8) -> 0.51770442 | H11: =H12/H$8 -> 0 | I11: =I12/I$8 -> 0 | J11: =J12/J$8 -> 0 | K11: =K12/K$8 -> 0 | L11: =L12/L$8 -> 0 | M11: =M12/M$8 -> 1.1476471 | N11: =N12/N$8 -> 1.8900565 | O11: =O12/O$8 -> 0
A12: Annual variable total excluding fuel & taxes | C12: =C13+C14 -> 131.192 | D12: =D13+D14 -> 3000.327 | E12: =E13+E14 -> 1393.6657 | F12: =F13+F14 -> 1814.0967 | G12: =G13+G14 -> 173.5344 | H12: =H13+H14 -> 0 | I12: =I13+I14 -> 0 | J12: =J13+J14 -> 0 | ... O12: =O13+O14 -> 0
A13: ='OLD-KPI'!A7 -> V-Oil & misc material | C13: =SUMIFS(Montant,StatsYear,C$5,StatsType,$A13) -> 131.192 | D13: =SUMIFS(Montant,StatsYear,D$5,StatsType,$A13) -> 142.577 | E13: =SUMIFS(Montant,StatsYear,E$5,StatsType,$A13) -> 660.5407 | F13: =SUMIFS(Montant,StatsYear,F$5,StatsType,$A13) -> 173.5344 | G13: =SUMIFS(Montant,StatsYear,G$5,StatsType,$A13) -> 173.5344 | H13: =SUMIFS(Montant,StatsYear,H$5,StatsType,$A13) -> 0 | I13: =SUMIFS(Montant,StatsYear,I$5,StatsType,$A13) -> 0 | J13: =SUMIFS(Montant,StatsYear,J$5,StatsType,$A13) -> 0 | ... O13: =SUMIFS(Montant,StatsYear,O$5,StatsType,$A13) -> 0
A14: ='OLD-KPI'!A8 -> V-Visit 50h & 100h | C14: =SUMIFS(Montant,StatsYear,C$5,StatsType,$A14) -> 0 | D14: =SUMIFS(Montant,StatsYear,D$5,StatsType,$A14) -> 2857.75 | E14: =SUMIFS(Montant,StatsYear,E$5,StatsType,$A14) -> 733.125 | F14: =SUMIFS(Montant,StatsYear,F$5,StatsType,$A14) -> 1640.5623 | G14: =SUMIFS(Montant,StatsYear,G$5,StatsType,$A14) -> 0 | H14: =SUMIFS(Montant,StatsYear,H$5,StatsType,$A14) -> 0 | I14: =SUMIFS(Montant,StatsYear,I$5,StatsType,$A14) -> 0 | J14: =SUMIFS(Montant,StatsYear,J$5,StatsType,$A14) -> 0 | ... O14: =SUMIFS(Montant,StatsYear,O$5,StatsType,$A14) -> 0
A15: Costs/hour fuel & taxes since 2018, current year | B15: =SUM(H17:N17)/SUM(H$8:N$8) -> 1.0951189 | H15: =H17/H$8 -> 1.2910798 | I15: =I17/I$8 -> 0 | J15: =J17/J$8 -> 0 | K15: =K17/K$8 -> 0 | L15: =L17/L$8 -> 2.6724138 | M15: =M17/M$8 -> 0.57647059 | N15: =N17/N$8 -> 0.70263488 | O15: =O17/O$8 -> 0
A16: Hourly fuel consumption, 2018 -> (liters) | B16: =SUM(H20:N20)/SUM(H$8:N$8) -> 0 | H16: =H20/H$8 -> 0 | I16: =I20/I$8 -> 0 | J16: =J20/J$8 -> 0 | K16: =K20/K$8 -> 0 | L16: =L20/L$8 -> 0 | M16: =M20/M$8 -> 0 | N16: =N20/N$8 -> 0 | O16: =O20/O$8 -> 0
A17: Total annual fuel & taxes | C17: =C18+C19 -> 0 | D17: =D18+D19 -> 0 | E17: =E18+E19 -> 0 | F17: =F18+F19 -> 0 | G17: =G18+G19 -> 0 | H17: =H18+H19 -> 110 | I17: =I18+I19 -> 0 | J17: =J18+J19 -> 0 | ... O17: =O18+O19 -> 0
A18: ='OLD-KPI'!A9 -> V-Landing Taxes | C18: =SUMIFS(Montant,StatsYear,C$5,StatsType,$A18) -> 0 | D18: =SUMIFS(Montant,StatsYear,D$5,StatsType,$A18) -> 0 | E18: =SUMIFS(Montant,StatsYear,E$5,StatsType,$A18) -> 0 | F18: =SUMIFS(Montant,StatsYear,F$5,StatsType,$A18) -> 0 | G18: =SUMIFS(Montant,StatsYear,G$5,StatsType,$A18) -> 0 | H18: =SUMIFS(Montant,StatsYear,H$5,StatsType,$A18) -> 110 | I18: =SUMIFS(Montant,StatsYear,I$5,StatsType,$A18) -> 0 | J18: =SUMIFS(Montant,StatsYear,J$5,StatsType,$A18) -> 0 | ... O18: =SUMIFS(Montant,StatsYear,O$5,StatsType,$A18) -> 0
A19: ='OLD-KPI'!A10 -> V-AVGAS | C19: =SUMIFS(Montant,StatsYear,C$5,StatsType,$A19) -> 0 | D19: =SUMIFS(Montant,StatsYear,D$5,StatsType,$A19) -> 0 | E19: =SUMIFS(Montant,StatsYear,E$5,StatsType,$A19) -> 0 | F19: =SUMIFS(Montant,StatsYear,F$5,StatsType,$A19) -> 0 | G19: =SUMIFS(Montant,StatsYear,G$5,StatsType,$A19) -> 0 | H19: =SUMIFS(Montant,StatsYear,H$5,StatsType,$A19) -> 0 | I19: =SUMIFS(Montant,StatsYear,I$5,StatsType,$A19) -> 0 | J19: =SUMIFS(Montant,StatsYear,J$5,StatsType,$A19) -> 0 | ... O19: =SUMIFS(Montant,StatsYear,O$5,StatsType,$A19) -> 0
A20: V-AVGAS volimue litres | C20: =SUMIF(StatsYear,C$5,VFuelVol) -> 0 | D20: =SUMIF(StatsYear,D$5,VFuelVol) -> 0 | E20: =SUMIF(StatsYear,E$5,VFuelVol) -> 0 | F20: =SUMIF(StatsYear,F$5,VFuelVol) -> 0 | G20: =SUMIF(StatsYear,G$5,VFuelVol) -> 0 | H20: =SUMIF(StatsYear,H$5,VFuelVol) -> 0 | I20: =SUMIF(StatsYear,I$5,VFuelVol) -> 0 | J20: =SUMIF(StatsYear,J$5,VFuelVol) -> 0 | ... O20: =SUMIF(StatsYear,O$5,VFuelVol) -> 0
A21: Recurring fixed costs
A22: Annual average since 2013 over the period | B22: =AVERAGE(C25:M25) -> 2583.4549
A23: Recommended monthly provision (statistics since 2013) | B23: =AVERAGE(C25:M25)/12 -> 215.28791
A24: Fixed hourly rate, 2018 -> now | B24: =SUM(H25:O25)/SUM(H$8:N$8) -> 6.5662178 | M24: =(M25/12*7)/M8 -> -11.921961 | N24: =(N25)/N8 -> 7.9463112 | O24: =(O25)/O8 -> 17.446796
A25: Total fixes récurrents annuel | C25: =SUM(C27:C34) -> 5629.694 | D25: =SUM(D27:D34) -> 2326.4845 | E25: =SUM(E27:E34) -> 8448.8151 | F25: =SUM(F27:F34) -> 6080.639 | G25: =SUM(G27:G34) -> 4665.2931 | H25: =SUM(H27:H34) -> 1479.985 | I25: =SUM(I27:I34) -> 159.12 | J25: =SUM(J27:J34) -> 540.8325 | ... O25: =SUM(O27:O34) -> 1247.4459 | Q25: Frais variables | R25: =B10 -> 1.6128233 | S25: =R25/(R25+R26) -> 0.19718978
A26: ='OLD-KPI'!A13 -> F-Manpwr & management (m-h) | C26: =SUMIFS(Man_hours,StatsYear,C$5,StatsType,$A26) -> 46.5 | D26: =SUMIFS(Man_hours,StatsYear,D$5,StatsType,$A26) -> 70.75 | E26: =SUMIFS(Man_hours,StatsYear,E$5,StatsType,$A26) -> 138.5 | F26: =SUMIFS(Man_hours,StatsYear,F$5,StatsType,$A26) -> 25.75 | G26: =SUMIFS(Man_hours,StatsYear,G$5,StatsType,$A26) -> 55 | H26: =SUMIFS(Man_hours,StatsYear,H$5,StatsType,$A26) -> 0.25 | I26: =SUMIFS(Man_hours,StatsYear,I$5,StatsType,$A26) -> 0 | J26: =SUMIFS(Man_hours,StatsYear,J$5,StatsType,$A26) -> 0 | ... O26: =SUMIFS(Man_hours,StatsYear,O$5,StatsType,$A26) -> 0 | Q26: Frais fixes | R26: =B24 -> 6.5662178 | S26: =R26/(R25+R26) -> 0.80281022
A27: ='OLD-KPI'!A12 -> F-Aircraft Insurance | C27: =SUMIFS(Montant,StatsYear,C$5,StatsType,$A27) -> 0 | D27: =SUMIFS(Montant,StatsYear,D$5,StatsType,$A27) -> 0 | E27: =SUMIFS(Montant,StatsYear,E$5,StatsType,$A27) -> 0 | F27: =SUMIFS(Montant,StatsYear,F$5,StatsType,$A27) -> 2912 | G27: =SUMIFS(Montant,StatsYear,G$5,StatsType,$A27) -> 0 | H27: =SUMIFS(Montant,StatsYear,H$5,StatsType,$A27) -> 1456 | I27: =SUMIFS(Montant,StatsYear,I$5,StatsType,$A27) -> 0 | J27: =SUMIFS(Montant,StatsYear,J$5,StatsType,$A27) -> 0 | ... O27: =SUMIFS(Montant,StatsYear,O$5,StatsType,$A27) -> 0
A28: ='OLD-KPI'!A14 -> F-Annual visit | C28: =SUMIFS(Montant,StatsYear,C$5,StatsType,$A28) -> 1837.3665 | D28: =SUMIFS(Montant,StatsYear,D$5,StatsType,$A28) -> 1674.4 | E28: =SUMIFS(Montant,StatsYear,E$5,StatsType,$A28) -> 1768.7 | F28: =SUMIFS(Montant,StatsYear,F$5,StatsType,$A28) -> 2025.0945 | G28: =SUMIFS(Montant,StatsYear,G$5,StatsType,$A28) -> 3289.5603 | H28: =SUMIFS(Montant,StatsYear,H$5,StatsType,$A28) -> 0 | I28: =SUMIFS(Montant,StatsYear,I$5,StatsType,$A28) -> 0 | J28: =SUMIFS(Montant,StatsYear,J$5,StatsType,$A28) -> 0 | ... O28: =SUMIFS(Montant,StatsYear,O$5,StatsType,$A28) -> 153.5859
A29: ='OLD-KPI'!A15 -> F-Avionics | C29: =SUMIFS(Montant,StatsYear,C$5,StatsType,$A29) -> 0 | D29: =SUMIFS(Montant,StatsYear,D$5,StatsType,$A29) -> 0 | E29: =SUMIFS(Montant,StatsYear,E$5,StatsType,$A29) -> 2403.2268 | F29: =SUMIFS(Montant,StatsYear,F$5,StatsType,$A29) -> 0 | G29: =SUMIFS(Montant,StatsYear,G$5,StatsType,$A29) -> 611.0325 | H29: =SUMIFS(Montant,StatsYear,H$5,StatsType,$A29) -> 23.985 | I29: =SUMIFS(Montant,StatsYear,I$5,StatsType,$A29) -> 0 | J29: =SUMIFS(Montant,StatsYear,J$5,StatsType,$A29) -> 0 | ... O29: =SUMIFS(Montant,StatsYear,O$5,StatsType,$A29) -> 0
A30: ='OLD-KPI'!A16 -> F-Hangar & insurance. | C30: =SUMIFS(Montant,StatsYear,C$5,StatsType,$A30) -> 0 | D30: =SUMIFS(Montant,StatsYear,D$5,StatsType,$A30) -> -4140 | E30: =SUMIFS(Montant,StatsYear,E$5,StatsType,$A30) -> -1800 | F30: =SUMIFS(Montant,StatsYear,F$5,StatsType,$A30) -> -1800 | G30: =SUMIFS(Montant,StatsYear,G$5,StatsType,$A30) -> -2106 | H30: =SUMIFS(Montant,StatsYear,H$5,StatsType,$A30) -> 0 | I30: =SUMIFS(Montant,StatsYear,I$5,StatsType,$A30) -> 0 | J30: =SUMIFS(Montant,StatsYear,J$5,StatsType,$A30) -> 0 | ... O30: =SUMIFS(Montant,StatsYear,O$5,StatsType,$A30) -> 1093.86
A31: ='OLD-KPI'!A17 -> F-ARC & CDN & ILR | C31: =SUMIFS(Montant,StatsYear,C$5,StatsType,$A31) -> 2038.681 | D31: =SUMIFS(Montant,StatsYear,D$5,StatsType,$A31) -> 0 | E31: =SUMIFS(Montant,StatsYear,E$5,StatsType,$A31) -> 3494.7499 | F31: =SUMIFS(Montant,StatsYear,F$5,StatsType,$A31) -> 2025.0945 | G31: =SUMIFS(Montant,StatsYear,G$5,StatsType,$A31) -> 1620.0522 | H31: =SUMIFS(Montant,StatsYear,H$5,StatsType,$A31) -> 0 | I31: =SUMIFS(Montant,StatsYear,I$5,StatsType,$A31) -> 0 | J31: =SUMIFS(Montant,StatsYear,J$5,StatsType,$A31) -> 0 | ... O31: =SUMIFS(Montant,StatsYear,O$5,StatsType,$A31) -> 0
A32: ='OLD-KPI'!A18 -> F-Time limit-misc. structure | C32: =SUMIFS(Montant,StatsYear,C$5,StatsType,$A32) -> 1736.799 | D32: =SUMIFS(Montant,StatsYear,D$5,StatsType,$A32) -> 3951.4345 | E32: =SUMIFS(Montant,StatsYear,E$5,StatsType,$A32) -> 2582.1384 | F32: =SUMIFS(Montant,StatsYear,F$5,StatsType,$A32) -> 918.45 | G32: =SUMIFS(Montant,StatsYear,G$5,StatsType,$A32) -> 1232.5716 | H32: =SUMIFS(Montant,StatsYear,H$5,StatsType,$A32) -> 0 | I32: =SUMIFS(Montant,StatsYear,I$5,StatsType,$A32) -> 159.12 | J32: =SUMIFS(Montant,StatsYear,J$5,StatsType,$A32) -> 0 | ... O32: =SUMIFS(Montant,StatsYear,O$5,StatsType,$A32) -> 0
A33: ='OLD-KPI'!A19 -> F-Airworthiness dir. | C33: =SUMIFS(Montant,StatsYear,C$5,StatsType,$A33) -> 0 | D33: =SUMIFS(Montant,StatsYear,D$5,StatsType,$A33) -> 0 | E33: =SUMIFS(Montant,StatsYear,E$5,StatsType,$A33) -> 0 | F33: =SUMIFS(Montant,StatsYear,F$5,StatsType,$A33) -> 0 | G33: =SUMIFS(Montant,StatsYear,G$5,StatsType,$A33) -> 0 | H33: =SUMIFS(Montant,StatsYear,H$5,StatsType,$A33) -> 0 | I33: =SUMIFS(Montant,StatsYear,I$5,StatsType,$A33) -> 0 | J33: =SUMIFS(Montant,StatsYear,J$5,StatsType,$A33) -> 330.2325 | ... O33: =SUMIFS(Montant,StatsYear,O$5,StatsType,$A33) -> 0
A34: ='OLD-KPI'!A20 -> F-Refill. | C34: =SUMIFS(Montant,StatsYear,C$5,StatsType,$A34) -> 16.8475 | D34: =SUMIFS(Montant,StatsYear,D$5,StatsType,$A34) -> 840.65 | E34: =SUMIFS(Montant,StatsYear,E$5,StatsType,$A34) -> 0 | F34: =SUMIFS(Montant,StatsYear,F$5,StatsType,$A34) -> 0 | G34: =SUMIFS(Montant,StatsYear,G$5,StatsType,$A34) -> 18.0765 | H34: =SUMIFS(Montant,StatsYear,H$5,StatsType,$A34) -> 0 | I34: =SUMIFS(Montant,StatsYear,I$5,StatsType,$A34) -> 0 | J34: =SUMIFS(Montant,StatsYear,J$5,StatsType,$A34) -> 210.6 | ... O34: =SUMIFS(Montant,StatsYear,O$5,StatsType,$A34) -> 0
A36: Non-recurring fixed costs
A37: Fixed, non-recurring hourly charges, 2018 -> now | B37: =SUM(H38:N38)/SUM(H$8:N$8) -> 87.973117
A38: Fixed non-recurring costs per year | C38: =C40+C42+SUM(C44:C46)+C53+SUM(C55:C57)+SUM(C48:C50) -> 0 | D38: =D40+D42+SUM(D44:D46)+D53+SUM(D55:D57)+SUM(D48:D50) -> 1148.9937 | E38: =E40+E42+SUM(E44:E46)+E53+SUM(E55:E57)+SUM(E48:E50) -> 5331.556 | F38: =F40+F42+SUM(F44:F46)+F53+SUM(F55:F57)+SUM(F48:F50) -> 5721.0666 | G38: =G40+G42+SUM(G44:G46)+G53+SUM(G55:G57)+SUM(G48:G50) -> 7492.2009 | H38: =H40+H42+SUM(H44:H46)+H53+SUM(H55:H57)+SUM(H48:H50) -> 7492.2009 | I38: =I40+I42+SUM(I44:I46)+I53+SUM(I55:I57)+SUM(I48:I50) -> 7492.2009 | J38: =J40+J42+SUM(J44:J46)+J53+SUM(J55:J57)+SUM(J48:J50) -> 6343.2071 | ... O38: =O40+O42+SUM(O44:O46)+O53+SUM(O55:O57)+SUM(O48:O50) -> 4369.7985
A39: ='OLD-KPI'!A22 -> Bottle O2 change | C39: =SUMIFS(Montant,StatsYear,C$5,StatsType,$A39) -> 0 | D39: =SUMIFS(Montant,StatsYear,D$5,StatsType,$A39) -> 0 | E39: =SUMIFS(Montant,StatsYear,E$5,StatsType,$A39) -> 0 | F39: =SUMIFS(Montant,StatsYear,F$5,StatsType,$A39) -> 0 | G39: =SUMIFS(Montant,StatsYear,G$5,StatsType,$A39) -> 0 | H39: =SUMIFS(Montant,StatsYear,H$5,StatsType,$A39) -> 0 | I39: =SUMIFS(Montant,StatsYear,I$5,StatsType,$A39) -> 0 | J39: =SUMIFS(Montant,StatsYear,J$5,StatsType,$A39) -> 0 | ... O39: =SUMIFS(Montant,StatsYear,O$5,StatsType,$A39) -> 0
A40: amortized over 15 years | M40: =$M$39/15 -> 22.04 | N40: =$M$39/15 -> 22.04 | O40: =$M$39/15 -> 22.04 | P40: =$M$39/15 -> 22.04 | Q40: =$M$39/15 -> 22.04 | R40: =$M$39/15 -> 22.04 | S40: =$M$39/15 -> 22.04 | T40: =$M$39/15 -> 22.04
A41: ='OLD-KPI'!A23 -> Change OVH engine | C41: =SUMIFS(Montant,StatsYear,C$5,StatsType,$A41) -> 0 | D41: =SUMIFS(Montant,StatsYear,D$5,StatsType,$A41) -> 0 | E41: =SUMIFS(Montant,StatsYear,E$5,StatsType,$A41) -> 62738.434 | F41: =SUMIFS(Montant,StatsYear,F$5,StatsType,$A41) -> 0 | G41: =SUMIFS(Montant,StatsYear,G$5,StatsType,$A41) -> 0 | H41: =SUMIFS(Montant,StatsYear,H$5,StatsType,$A41) -> 0 | I41: =SUMIFS(Montant,StatsYear,I$5,StatsType,$A41) -> 0 | J41: =SUMIFS(Montant,StatsYear,J$5,StatsType,$A41) -> 0 | ... O41: =SUMIFS(Montant,StatsYear,O$5,StatsType,$A41) -> 0
...

Sheet OLD-KPI
A1: Calculation Parameters
A2: This file is used to calculate Mooney's spending statistics
A3: The two sources of invoices are (1) GAM, LuxAirport landing fees and others, (2) LuxFuel, Total, BP and others
A4: The items to be allocated for the statistics are
A5: Spending categories | B5: Total 2013-2024
A6: ---- | D6: Variable costs
A7: V-Oil & misc material | B7: =SUM('OLD-Stats'!C13:O13) -> 1378.9285 | D7: Emergency oil
A8: V-Visit 50h & 100h | B8: =SUM('OLD-Stats'!C14:O14) -> 5382.0748 | D8: 50-hour and 100-hour visits + parts
A9: V-Landing Taxes | B9: =SUM('OLD-Stats'!C18:O18) -> 525
A10: V-AVGAS | B10: =SUM('OLD-Stats'!C19:O19) -> 0
A11: ---- | D11: Recurring fixed costs
A12: F-Aircraft Insurance | B12: =SUM('OLD-Stats'!C27:O27) -> 4057.95 | D12: Aviabel Insurance
A13: F-Manpwr & management (m-h) | B13: =SUM('OLD-Stats'!C26:O26) -> 351.25 | D13: GAM Workforce
A14: F-Annual visit | B14: =SUM('OLD-Stats'!C28:O28) -> 10764.058 | D14: GAM "Annual inspection" excluding parts
A15: F-Avionics | B15: =SUM('OLD-Stats'!C29:O29) -> 3868.0878 | D15: Avionics, W&B, Jeppesen Subscriptions, bank
A16: F-Hangar & insurance. | B16: =SUM('OLD-Stats'!C30:O30) -> -9837.97 | D16: Hangar rental, insurance, repairs
A17: F-ARC & CDN & ILR | B17: =SUM('OLD-Stats'!C31:O31) -> 9178.5776 | D17: GAM ARC renew & redev. ILR, AMP
A18: F-Time limit-misc. structure | B18: =SUM('OLD-Stats'!C32:O32) -> 10851.661 | D18: Miscellaneous, fire extinguisher, first aid, airbrake, rudder trim
A19: F-Airworthiness dir. | B19: =SUM('OLD-Stats'!C33:O33) -> 330.2325 | D19: Application of the Airworthiness Directives
A20: F-Refill. | B20: =SUM('OLD-Stats'!C34:O34) -> 1086.174 | D20: Refill O2, Hydraulics
A21: --- | D21: Exceptional fixed costs
A22: Bottle O2 change | B22: =SUM('OLD-Stats'!C39:O39) -> 330.6 | C22: over 15 y | D22: Oxygen cylinder (2023), 15 y
A23: Change OVH engine | B23: =SUM('OLD-Stats'!C41:O41) -> 62738.434 | C23: over 12 y | D23: Engine OVH, TBO 12y (2014)
A24: OVH propeller regulator | B24: =SUM('OLD-Stats'!C43:O43) -> 2484.6705 | C24: over 5 y | D24: Propeller OVH, TBO 5y (2014, -16, -18, -20, -25)
A25: Change hub, OVH propeller | B25: =SUM('OLD-Stats'!C47:O47) -> 6893.9625 | C25: over 6 y | D25: Propeller OVH, TBO 6y (2025, -30)
A26: OVH conduits | B26: =SUM('OLD-Stats'!C51:O51) -> 6763.1616 | C26: over 6y | D26: Engine piping, 6y (2017-24,-30)
A27: GTN 650 | B27: =SUM('OLD-Stats'!C54:O54) -> 10769.606 | C27: over 8 y | D27: GTN650, 8y (2017)
A28: Landing gear replacement | B28: =SUM('OLD-Stats'!C59:O59) -> -24222.51 | C28: perpétuel | D28: Hard landing 2020, perpetual
A29: Raft, life jackets, O2 masks | B29: =SUM('OLD-Stats'!C60:O60) -> 2770.5366 | C29: over 10 tears | D29: Miscellaneous 10 y
A30: Change hub, OVH propeller | B30: =SUM('OLD-Stats'!C58:O58) -> 0 | C30: perpetual | D30: Propeller hub fault, perpetual
A32: Note: OVH that account for less than 5 years are counted directly in the year of payment and not distributed over time.
A33: Note: Variable costs are underrepresented because the aircraft flew very little from 2013 to 2018.
A34: Note: Mechanical hours per hour of service from 2013 to 2025 | D34: =B13/('OLD-Stats'!O7-'OLD-Stats'!C6) -> 0.52106512
A35: Note: Mechanical hours per hour of service from 2018 to 2026 | D35: =SUM('OLD-Stats'!H26:O26)/('OLD-Stats'!O7-'OLD-Stats'!H6) -> 0.026774369
